Workbook
Name Acs: [1]Constants!$C$5
Name Acs: Constants!$C$5
Name Fsw: [1]Calculations!$B$15
Name Fsw: Calculations!$B$15
Name gm: [1]Constants!$C$4
Name gm: Constants!$C$4
Name I_Channel: [1]Calculations!$B$32
Name I_Channel: Calculations!$B$29
Name I_Channel_Design: [1]Calculations!$B$25
Name I_Channel_Design: Calculations!$B$25
Name I_Channel_Peak_No_Ilimit: [1]Calculations!$B$75
Name I_Channel_Peak_No_Ilimit: Calculations!$B$65
Name I_Channel_Peak_Select: [1]Calculations!$B$77
Name I_Channel_Peak_Select: Calculations!$B$67
Name I_Channel_Select: [1]Compensation!#REF!
Name I_Channel_Select: Compensation!#REF!
Name I12_Select: [1]Design_Converter!#REF!
Name I12_Select: Design_Converter!#REF!
Name I48_Select: [1]Design_Converter!#REF!
Name I48_Select: Design_Converter!#REF!
Name IL_Comp_Ccomp: [1]Calculations!$B$156*(10^(-9))
Name IL_Comp_Ccomp: Calculations!$B$146*(10^(-9))
Name IL_Comp_Chf: [1]Calculations!$B$158*(10^-9)
Name IL_Comp_Chf: Calculations!$B$148*(10^-9)
Name IL_Comp_Rcomp: [1]Calculations!$B$154*1000
Name IL_Comp_Rcomp: Calculations!$B$144*1000
Name ISETA_Max: Constants!$C$46
Name Lm: [1]Calculations!$B$43*(10^-6)
Name Lm: Calculations!$B$38*(10^-6)
Name Lm_DCR: [1]Design_Converter!$B$39/(1000)
Name Lm_DCR: Design_Converter!$B$38/(1000)
Name np: [1]Calculations!$B$24
Name np: Calculations!$B$24
Name np_select: [1]Compensation!#REF!
Name np_select: Compensation!#REF!
Name Ramp_C: [1]Design_Converter!#REF!*(10^(-9))
Name Ramp_C: Design_Converter!$B$62*(10^(-9))
Name Ramp_R: [1]Design_Converter!#REF!*1000
Name Ramp_R: Design_Converter!$B$64*1000
Name Rcs: [1]Calculations!$B$31/1000
Name Rcs: Calculations!$B$28/1000
Name Schematic: INDIRECT(#REF!)
Name Schematic: INDIRECT(Schematic!$A$2)
Name schematic_1: #REF!
Name schematic_1: Schematic!$B$4
Name V12_Max: [1]Calculations!$B$13
Name V12_Max: Calculations!$B$13
Name V12_Min: [1]Calculations!$B$11
Name V12_Min: Calculations!$B$11
Name V12_Nom: [1]Calculations!$B$12
Name V12_Nom: Calculations!$B$12
Name V12_Select: [1]Compensation!#REF!
Name V12_Select: Compensation!#REF!
Name V12_Vripple: [1]Design_Converter!#REF!
Name V12_Vripple: Design_Converter!#REF!
Name V48_Max: [1]Calculations!$B$9
Name V48_Max: Calculations!$B$9
Name V48_Min: [1]Calculations!$B$7
Name V48_Min: Calculations!$B$7
Name V48_Nom: [1]Calculations!$B$8

Sheet Design_Converter
A1: LM5170 Bi-Directional DC/DC Converter Design Tool
C5: User Input | G5: ABOUT | R5: Terms of Use
A8: 1. Design Parameters
A10: High Voltage Input Parameters | G10: Typical Application Schematic
A11: HV Port Minimum Voltage | B11: 30 | C11: V
A12: HV Port Nominal Voltage | B12: 50 | C12: V
A13: HV Port Maximum Voltage | B13: 85 | C13: V
A15: Low Voltage Rail Parameters
A16: LV Port Minimum Voltage | B16: 18.5 | C16: V
A17: LV Port Nominal Voltage | B17: 20 | C17: V
A18: LV Port Maximum Voltage | B18: 26 | C18: V
A20: Switching Frequency
A21: Selected Switching Frequency | B21: 400 | C21: kHz
A22: Oscillator Set Resistor (ROSC) | B22: =Calculations!B16 -> 10 | C22: kΩ
A24: Current Range/ Number of Phases
A25: Total Number of Phases | B25: 2
A26: Total Low Voltage Rail Current | B26: 45 | C26: A
A27: Calculated Sense Resistor (RCS1, RCS2) | B27: =Calculations!B27 -> 2.2222222 | C27: mΩ
A28: Selected Sense Resistor (RCS1, RCS2) | B28: 1 | C28: mΩ
A29: Maximum Average Inductor Current Per Channel | B29: =VCS_Max/Rcs -> 50 | C29: A
A30: Maximum Low Voltage Rail Current | B30: =Calculations!B31 -> 100 | C30: A
A32: 2. Inductor Selection
A34: Inductor Selection
A35: Peak-to-Peak Ripple Ratio | B35: 30.6 | C35: %
A36: Calculated Inductance Value | B36: =Calculations!B37 -> 5.5534196 | C36: uH
A37: Selected Inductance Value (LM1,LM2) | B37: 4.7 | C37: uH
A38: Inductor DCR | B38: 2.4 | C38: mΩ
A39: Maximum Inductor Peak Current | B39: =I_Channel_Peak_No_Ilimit -> 26.567584 | C39: A
A41: 3. Inductor Current Limiting
A43: Inductor Peak Current Limit
A44: Current Limit Margin Above Maximum Inductor Current | B44: 10 | C44: %
A45: Selected Inductor Peak Current Limit | B45: =I_Channel_Peak_Select -> 29.224343 | C45: A
A46: Calculated IPK Resistor (RIPK) | B46: =Calculations!B68 -> 26.567584 | C46: kΩ
A47: Selected IPK Resistor (RIPK) | B47: 26 | C47: kΩ
A48: Actual Inductor Peak Current Limit | B48: =Calculations!B70 -> 28.6 | C48: A
A50: 4. Output Capacitance
A52: Low Voltage Port
A53: Selected Low Voltage Port Capacitance (COUT_LV) | B53: 937.6 | C53: uF
A54: Low Voltage Capacitance ESR | B54: 112 | C54: mΩ
A55: High Voltage Port
...

Sheet Licenses
A5: Version Number | B5: =LOOKUP(2,1/((A37:A46)<>""),(A37:A46)) -> 1.1.0
A35: Version History
A36: Version | B36: Change List Description
A37: 1.0.0 | B37: Initial Release
A38: 1.1.0 | B38: Recommended ramp resistor changed; slight change of ROVPA and ROVPB

Sheet Calculations
N2: Value V Load Current
P4: V48_Min to V12_NOM | T4: V48_Nom to V12_Nom | X4: V48_Max to V12_Nom | AB4: V12_Min to V48_Nom | AF4: V12_Nom to V48_Nom | AJ4: V12_Max to V48_Nom
D5: Spec Violation | N5: Current Sense Voltage | O5: Buck Channel Current | P5: HO Duty Cycle | Q5: LO Duty Cycle | R5: Ripple Current | S5: Peak Current | T5: HO Duty Cycle | U5: LO Duty Cycle | V5: Ripple Current | W5: Peak Current | X5: HO Duty Cycle | Y5: LO Duty Cycle | Z5: Ripple Current | AA5: Peak Current | AB5: HO Duty Cycle | AC5: LO Duty Cycle | AD5: Ripple Current | AE5: Peak Current | AF5: HO Duty Cycle | AG5: LO Duty Cycle | AH5: Ripple Current | AI5: Peak Current | AJ5: HO Duty Cycle | AK5: LO Duty Cycle | AL5: Ripple Current | AM5: Peak Current
A6: V48 Rail Selection | E6: Need to Add flags for input voltage range | N6: 0 | O6: =N6/Rcs -> 0 | P6: =IF($O6<((V48_Min-V12_Nom)*V12_Nom)/((2*Lm*Fsw)*V48_Min),SQRT((2*$O6*Lm*Fsw*V12_Nom)/(V48_Min*(V48_Min-V12_Nom))),(V12_Nom/V48_Min)) -> 0 | Q6: =IF($O6<((V48_Min-V12_Nom)*V12_Nom)/((2*Lm*Fsw)*V48_Min),SQRT((2*$O6*Lm*Fsw*V12_Nom)/(V48_Min*(V48_Min-V12_Nom)))*((V48_Min-V12_Nom)/(V12_Nom)),1-(V12_Nom/V48_Min)) -> 0 | R6: =IF($O6<((V48_Min-V12_Nom)*V12_Nom)/((2*Lm*Fsw)*V48_Min),(P6/(Fsw*Lm))*(V48_Min-V12_Nom),((P6/(Fsw*Lm))*(V48_Min-V12_Nom))) -> 0 | S6: =IF($O6<((V48_Min-V12_Nom)*V12_Nom)/((2*Lm*Fsw)*V48_Min),(P6/(Fsw*Lm))*(V48_Min-V12_Nom),(R6/2)+$O6) -> 0 | T6: =IF($O6<((V48_Nom-V12_Nom)*V12_Nom)/((2*Lm*Fsw)*V48_Nom),SQRT((2*$O6*Lm*Fsw*V12_Nom)/(V48_Nom*(V48_Nom-V12_Nom))),(V12_Nom/V48_Nom)) -> 0 | U6: =IF($O6<((V48_Nom-V12_Nom)*V12_Nom)/((2*Lm*Fsw)*V48_Nom),SQRT((2*$O6*Lm*Fsw*V12_Nom)/(V48_Nom*(V48_Nom-V12_Nom)))*((V48_Nom-V12_Nom)/(V12_Nom)),1-(V12_Nom/V48_Nom)) -> 0 | V6: =IF($O6<((V48_Nom-V12_Nom)*V12_Nom)/((2*Lm*Fsw)*V48_Nom),(T6/(Fsw*Lm))*(V48_Nom-V12_Nom),((T6/(Fsw*Lm))*(V48_Nom-V12_Nom))) -> 0 | W6: =IF($O6<((V48_Nom-V12_Nom)*V12_Nom)/((2*Lm*Fsw)*V48_Nom),(T6/(Fsw*Lm))*(V48_Nom-V12_Nom),(V6/2)+$O6) -> 0 | X6: =IF($O6<((V48_Max-V12_Nom)*V12_Nom)/((2*Lm*Fsw)*V48_Max),SQRT((2*$O6*Lm*Fsw*V12_Nom)/(V48_Max*(V48_Max-V12_Nom))),(V12_Nom/V48_Max)) -> 0 | Y6: =IF($O6<((V48_Max-V12_Nom)*V12_Nom)/((2*Lm*Fsw)*V48_Max),SQRT((2*$O6*Lm*Fsw*V12_Nom)/(V48_Max*(V48_Max-V12_Nom)))*((V48_Max-V12_Nom)/(V12_Nom)),1-(V12_Nom/V48_Max)) -> 0 | Z6: =IF($O6<((V48_Max-V12_Nom)*V12_Nom)/((2*Lm*Fsw)*V48_Max),(X6/(Fsw*Lm))*(V48_Max-V12_Nom),((X6/(Fsw*Lm))*(V48_Max-V12_Nom))) -> 0 | AA6: =IF($O6<((V48_Max-V12_Nom)*V12_Nom)/((2*Lm*Fsw)*V48_Max),(X6/(Fsw*Lm))*(V48_Max-V12_Nom),(Z6/2)+$O6) -> 0 | AB6: =IF($O6<((V48_Nom-V12_Min)*V12_Min)/((2*Lm*Fsw)*V48_Nom),SQRT((2*$O6*Lm*Fsw*V12_Min)/(V48_Nom*(V48_Nom-V12_Min))),(V12_Min/V48_Nom)) -> 0 | AC6: =IF($O6<((V48_Nom-V12_Min)*V12_Min)/((2*Lm*Fsw)*V48_Nom),SQRT((2*$O6*Lm*Fsw*V12_Min)/(V48_Nom*(V48_Nom-V12_Min)))*((V48_Nom-V12_Min)/(V12_Min)),1-(V12_Min/V48_Nom)) -> 0 | AD6: =IF($O6<((V48_Nom-V12_Min)*V12_Min)/((2*Lm*Fsw)*V48_Nom),(AB6/(Fsw*Lm))*(V48_Nom-V12_Min),((AB6/(Fsw*Lm))*(V48_Nom-V12_Min))) -> 0 | AE6: =IF($O6<((V48_Nom-V12_Min)*V12_Min)/((2*Lm*Fsw)*V48_Nom),(AB6/(Fsw*Lm))*(V48_Nom-V12_Min),(AD6/2)+$O6) -> 0 | AF6: =IF($O6<((V48_Nom-V12_Nom)*V12_Nom)/((2*Lm*Fsw)*V48_Nom),SQRT((2*$O6*Lm*Fsw*V12_Nom)/(V48_Nom*(V48_Nom-V12_Nom))),(V12_Nom/V48_Nom)) -> 0 | AG6: =IF($O6<((V48_Nom-V12_Nom)*V12_Nom)/((2*Lm*Fsw)*V48_Nom),SQRT((2*$O6*Lm*Fsw*V12_Nom)/(V48_Nom*(V48_Nom-V12_Nom)))*((V48_Nom-V12_Nom)/(V12_Nom)),1-(V12_Nom/V48_Nom)) -> 0 | AH6: =IF($O6<((V48_Nom-V12_Nom)*V12_Nom)/((2*Lm*Fsw)*V48_Nom),(AF6/(Fsw*Lm))*(V48_Nom-V12_Nom),((AF6/(Fsw*Lm))*(V48_Nom-V12_Nom))) -> 0 | AI6: =IF($O6<((V48_Nom-V12_Nom)*V12_Nom)/((2*Lm*Fsw)*V48_Nom),(AF6/(Fsw*Lm))*(V48_Nom-V12_Nom),(AH6/2)+$O6) -> 0 | AJ6: =IF($O6<((V48_Nom-V12_Max)*V12_Max)/((2*Lm*Fsw)*V48_Nom),SQRT((2*$O6*Lm*Fsw*V12_Max)/(V48_Nom*(V48_Nom-V12_Max))),(V12_Max/V48_Nom)) -> 0 | AK6: =IF($O6<((V48_Nom-V12_Max)*V12_Max)/((2*Lm*Fsw)*V48_Nom),SQRT((2*$O6*Lm*Fsw*V12_Max)/(V48_Nom*(V48_Nom-V12_Max)))*((V48_Nom-V12_Max)/(V12_Max)),1-(V12_Max/V48_Nom)) -> 0 | AL6: =IF($O6<((V48_Nom-V12_Max)*V12_Max)/((2*Lm*Fsw)*V48_Nom),(AJ6/(Fsw*Lm))*(V48_Nom-V12_Max),((AJ6/(Fsw*Lm))*(V48_Nom-V12_Max))) -> 0 | AM6: =IF($O6<((V48_Nom-V12_Max)*V12_Max)/((2*Lm*Fsw)*V48_Nom),(AJ6/(Fsw*Lm))*(V48_Nom-V12_Max),(AL6/2)+$O6) -> 0
A7: V48_Min | B7: =Design_Converter!B11 -> 30 | C7: V | E7: Minimum 48V Rail Voltage | J7: User Input | N7: 0.001 | O7: =N7/Rcs -> 1 | P7: =IF($O7<((V48_Min-V12_Nom)*V12_Nom)/((2*Lm*Fsw)*V48_Min),SQRT((2*$O7*Lm*Fsw*V12_Nom)/(V48_Min*(V48_Min-V12_Nom))),(V12_Nom/V48_Min)) -> 0.50066622 | Q7: =IF($O7<((V48_Min-V12_Nom)*V12_Nom)/((2*Lm*Fsw)*V48_Min),SQRT((2*$O7*Lm*Fsw*V12_Nom)/(V48_Min*(V48_Min-V12_Nom)))*((V48_Min-V12_Nom)/(V12_Nom)),1-(V12_Nom/V48_Min)) -> 0.25033311 | R7: =IF($O7<((V48_Min-V12_Nom)*V12_Nom)/((2*Lm*Fsw)*V48_Min),(P7/(Fsw*Lm))*(V48_Min-V12_Nom),((P7/(Fsw*Lm))*(V48_Min-V12_Nom))) -> 2.6631182 | S7: =IF($O7<((V48_Min-V12_Nom)*V12_Nom)/((2*Lm*Fsw)*V48_Min),(P7/(Fsw*Lm))*(V48_Min-V12_Nom),(R7/2)+$O7) -> 2.6631182 | T7: =IF($O7<((V48_Nom-V12_Nom)*V12_Nom)/((2*Lm*Fsw)*V48_Nom),SQRT((2*$O7*Lm*Fsw*V12_Nom)/(V48_Nom*(V48_Nom-V12_Nom))),(V12_Nom/V48_Nom)) -> 0.22390474 | U7: =IF($O7<((V48_Nom-V12_Nom)*V12_Nom)/((2*Lm*Fsw)*V48_Nom),SQRT((2*$O7*Lm*Fsw*V12_Nom)/(V48_Nom*(V48_Nom-V12_Nom)))*((V48_Nom-V12_Nom)/(V12_Nom)),1-(V12_Nom/V48_Nom)) -> 0.33585711 | V7: =IF($O7<((V48_Nom-V12_Nom)*V12_Nom)/((2*Lm*Fsw)*V48_Nom),(T7/(Fsw*Lm))*(V48_Nom-V12_Nom),((T7/(Fsw*Lm))*(V48_Nom-V12_Nom))) -> 3.572948 | W7: =IF($O7<((V48_Nom-V12_Nom)*V12_Nom)/((2*Lm*Fsw)*V48_Nom),(T7/(Fsw*Lm))*(V48_Nom-V12_Nom),(V7/2)+$O7) -> 3.572948 | X7: =IF($O7<((V48_Max-V12_Nom)*V12_Nom)/((2*Lm*Fsw)*V48_Max),SQRT((2*$O7*Lm*Fsw*V12_Nom)/(V48_Max*(V48_Max-V12_Nom))),(V12_Nom/V48_Max)) -> 0.11666559 | Y7: =IF($O7<((V48_Max-V12_Nom)*V12_Nom)/((2*Lm*Fsw)*V48_Max),SQRT((2*$O7*Lm*Fsw*V12_Nom)/(V48_Max*(V48_Max-V12_Nom)))*((V48_Max-V12_Nom)/(V12_Nom)),1-(V12_Nom/V48_Max)) -> 0.37916317 | Z7: =IF($O7<((V48_Max-V12_Nom)*V12_Nom)/((2*Lm*Fsw)*V48_Max),(X7/(Fsw*Lm))*(V48_Max-V12_Nom),((X7/(Fsw*Lm))*(V48_Max-V12_Nom))) -> 4.0336507 | AA7: =IF($O7<((V48_Max-V12_Nom)*V12_Nom)/((2*Lm*Fsw)*V48_Max),(X7/(Fsw*Lm))*(V48_Max-V12_Nom),(Z7/2)+$O7) -> 4.0336507 | AB7: =IF($O7<((V48_Nom-V12_Min)*V12_Min)/((2*Lm*Fsw)*V48_Nom),SQRT((2*$O7*Lm*Fsw*V12_Min)/(V48_Nom*(V48_Nom-V12_Min))),(V12_Min/V48_Nom)) -> 0.21015489 | AC7: =IF($O7<((V48_Nom-V12_Min)*V12_Min)/((2*Lm*Fsw)*V48_Nom),SQRT((2*$O7*Lm*Fsw*V12_Min)/(V48_Nom*(V48_Nom-V12_Min)))*((V48_Nom-V12_Min)/(V12_Min)),1-(V12_Min/V48_Nom)) -> 0.35783131 | AD7: =IF($O7<((V48_Nom-V12_Min)*V12_Min)/((2*Lm*Fsw)*V48_Nom),(AB7/(Fsw*Lm))*(V48_Nom-V12_Min),((AB7/(Fsw*Lm))*(V48_Nom-V12_Min))) -> 3.5212123 | AE7: =IF($O7<((V48_Nom-V12_Min)*V12_Min)/((2*Lm*Fsw)*V48_Nom),(AB7/(Fsw*Lm))*(V48_Nom-V12_Min),(AD7/2)+$O7) -> 3.5212123 | AF7: =IF($O7<((V48_Nom-V12_Nom)*V12_Nom)/((2*Lm*Fsw)*V48_Nom),SQRT((2*$O7*Lm*Fsw*V12_Nom)/(V48_Nom*(V48_Nom-V12_Nom))),(V12_Nom/V48_Nom)) -> 0.22390474 | AG7: =IF($O7<((V48_Nom-V12_Nom)*V12_Nom)/((2*Lm*Fsw)*V48_Nom),SQRT((2*$O7*Lm*Fsw*V12_Nom)/(V48_Nom*(V48_Nom-V12_Nom)))*((V48_Nom-V12_Nom)/(V12_Nom)),1-(V12_Nom/V48_Nom)) -> 0.33585711 | AH7: =IF($O7<((V48_Nom-V12_Nom)*V12_Nom)/((2*Lm*Fsw)*V48_Nom),(AF7/(Fsw*Lm))*(V48_Nom-V12_Nom),((AF7/(Fsw*Lm))*(V48_Nom-V12_Nom))) -> 3.572948 | AI7: =IF($O7<((V48_Nom-V12_Nom)*V12_Nom)/((2*Lm*Fsw)*V48_Nom),(AF7/(Fsw*Lm))*(V48_Nom-V12_Nom),(AH7/2)+$O7) -> 3.572948 | AJ7: =IF($O7<((V48_Nom-V12_Max)*V12_Max)/((2*Lm*Fsw)*V48_Nom),SQRT((2*$O7*Lm*Fsw*V12_Max)/(V48_Nom*(V48_Nom-V12_Max))),(V12_Max/V48_Nom)) -> 0.28542366 | AK7: =IF($O7<((V48_Nom-V12_Max)*V12_Max)/((2*Lm*Fsw)*V48_Nom),SQRT((2*$O7*Lm*Fsw*V12_Max)/(V48_Nom*(V48_Nom-V12_Max)))*((V48_Nom-V12_Max)/(V12_Max)),1-(V12_Max/V48_Nom)) -> 0.263468 | AL7: =IF($O7<((V48_Nom-V12_Max)*V12_Max)/((2*Lm*Fsw)*V48_Nom),(AJ7/(Fsw*Lm))*(V48_Nom-V12_Max),((AJ7/(Fsw*Lm))*(V48_Nom-V12_Max))) -> 3.6437063 | AM7: =IF($O7<((V48_Nom-V12_Max)*V12_Max)/((2*Lm*Fsw)*V48_Nom),(AJ7/(Fsw*Lm))*(V48_Nom-V12_Max),(AL7/2)+$O7) -> 3.6437063
A8: V48_Nom | B8: =Design_Converter!B12 -> 50 | C8: V | E8: Nominal 48V Rail Voltage | J8: Calculated Value | N8: 0.002 | O8: =N8/Rcs -> 2 | P8: =IF($O8<((V48_Min-V12_Nom)*V12_Nom)/((2*Lm*Fsw)*V48_Min),SQRT((2*$O8*Lm*Fsw*V12_Nom)/(V48_Min*(V48_Min-V12_Nom))),(V12_Nom/V48_Min)) -> 0.66666667 | Q8: =IF($O8<((V48_Min-V12_Nom)*V12_Nom)/((2*Lm*Fsw)*V48_Min),SQRT((2*$O8*Lm*Fsw*V12_Nom)/(V48_Min*(V48_Min-V12_Nom)))*((V48_Min-V12_Nom)/(V12_Nom)),1-(V12_Nom/V48_Min)) -> 0.33333333 | R8: =IF($O8<((V48_Min-V12_Nom)*V12_Nom)/((2*Lm*Fsw)*V48_Min),(P8/(Fsw*Lm))*(V48_Min-V12_Nom),((P8/(Fsw*Lm))*(V48_Min-V12_Nom))) -> 3.5460993 | S8: =IF($O8<((V48_Min-V12_Nom)*V12_Nom)/((2*Lm*Fsw)*V48_Min),(P8/(Fsw*Lm))*(V48_Min-V12_Nom),(R8/2)+$O8) -> 3.7730496 | T8: =IF($O8<((V48_Nom-V12_Nom)*V12_Nom)/((2*Lm*Fsw)*V48_Nom),SQRT((2*$O8*Lm*Fsw*V12_Nom)/(V48_Nom*(V48_Nom-V12_Nom))),(V12_Nom/V48_Nom)) -> 0.31664912 | U8: =IF($O8<((V48_Nom-V12_Nom)*V12_Nom)/((2*Lm*Fsw)*V48_Nom),SQRT((2*$O8*Lm*Fsw*V12_Nom)/(V48_Nom*(V48_Nom-V12_Nom)))*((V48_Nom-V12_Nom)/(V12_Nom)),1-(V12_Nom/V48_Nom)) -> 0.47497368 | V8: =IF($O8<((V48_Nom-V12_Nom)*V12_Nom)/((2*Lm*Fsw)*V48_Nom),(T8/(Fsw*Lm))*(V48_Nom-V12_Nom),((T8/(Fsw*Lm))*(V48_Nom-V12_Nom))) -> 5.0529115 | W8: =IF($O8<((V48_Nom-V12_Nom)*V12_Nom)/((2*Lm*Fsw)*V48_Nom),(T8/(Fsw*Lm))*(V48_Nom-V12_Nom),(V8/2)+$O8) -> 5.0529115 | X8: =IF($O8<((V48_Max-V12_Nom)*V12_Nom)/((2*Lm*Fsw)*V48_Max),SQRT((2*$O8*Lm*Fsw*V12_Nom)/(V48_Max*(V48_Max-V12_Nom))),(V12_Nom/V48_Max)) -> 0.16499006 | Y8: =IF($O8<((V48_Max-V12_Nom)*V12_Nom)/((2*Lm*Fsw)*V48_Max),SQRT((2*$O8*Lm*Fsw*V12_Nom)/(V48_Max*(V48_Max-V12_Nom)))*((V48_Max-V12_Nom)/(V12_Nom)),1-(V12_Nom/V48_Max)) -> 0.53621769 | Z8: =IF($O8<((V48_Max-V12_Nom)*V12_Nom)/((2*Lm*Fsw)*V48_Max),(X8/(Fsw*Lm))*(V48_Max-V12_Nom),((X8/(Fsw*Lm))*(V48_Max-V12_Nom))) -> 5.7044435 | AA8: =IF($O8<((V48_Max-V12_Nom)*V12_Nom)/((2*Lm*Fsw)*V48_Max),(X8/(Fsw*Lm))*(V48_Max-V12_Nom),(Z8/2)+$O8) -> 5.7044435 | AB8: =IF($O8<((V48_Nom-V12_Min)*V12_Min)/((2*Lm*Fsw)*V48_Nom),SQRT((2*$O8*Lm*Fsw*V12_Min)/(V48_Nom*(V48_Nom-V12_Min))),(V12_Min/V48_Nom)) -> 0.2972039 | AC8: =IF($O8<((V48_Nom-V12_Min)*V12_Min)/((2*Lm*Fsw)*V48_Nom),SQRT((2*$O8*Lm*Fsw*V12_Min)/(V48_Nom*(V48_Nom-V12_Min)))*((V48_Nom-V12_Min)/(V12_Min)),1-(V12_Min/V48_Nom)) -> 0.50604989 | AD8: =IF($O8<((V48_Nom-V12_Min)*V12_Min)/((2*Lm*Fsw)*V48_Nom),(AB8/(Fsw*Lm))*(V48_Nom-V12_Min),((AB8/(Fsw*Lm))*(V48_Nom-V12_Min))) -> 4.9797462 | AE8: =IF($O8<((V48_Nom-V12_Min)*V12_Min)/((2*Lm*Fsw)*V48_Nom),(AB8/(Fsw*Lm))*(V48_Nom-V12_Min),(AD8/2)+$O8) -> 4.9797462 | AF8: =IF($O8<((V48_Nom-V12_Nom)*V12_Nom)/((2*Lm*Fsw)*V48_Nom),SQRT((2*$O8*Lm*Fsw*V12_Nom)/(V48_Nom*(V48_Nom-V12_Nom))),(V12_Nom/V48_Nom)) -> 0.31664912 | AG8: =IF($O8<((V48_Nom-V12_Nom)*V12_Nom)/((2*Lm*Fsw)*V48_Nom),SQRT((2*$O8*Lm*Fsw*V12_Nom)/(V48_Nom*(V48_Nom-V12_Nom)))*((V48_Nom-V12_Nom)/(V12_Nom)),1-(V12_Nom/V48_Nom)) -> 0.47497368 | AH8: =IF($O8<((V48_Nom-V12_Nom)*V12_Nom)/((2*Lm*Fsw)*V48_Nom),(AF8/(Fsw*Lm))*(V48_Nom-V12_Nom),((AF8/(Fsw*Lm))*(V48_Nom-V12_Nom))) -> 5.0529115 | AI8: =IF($O8<((V48_Nom-V12_Nom)*V12_Nom)/((2*Lm*Fsw)*V48_Nom),(AF8/(Fsw*Lm))*(V48_Nom-V12_Nom),(AH8/2)+$O8) -> 5.0529115 | AJ8: =IF($O8<((V48_Nom-V12_Max)*V12_Max)/((2*Lm*Fsw)*V48_Nom),SQRT((2*$O8*Lm*Fsw*V12_Max)/(V48_Nom*(V48_Nom-V12_Max))),(V12_Max/V48_Nom)) -> 0.40365001 | AK8: =IF($O8<((V48_Nom-V12_Max)*V12_Max)/((2*Lm*Fsw)*V48_Nom),SQRT((2*$O8*Lm*Fsw*V12_Max)/(V48_Nom*(V48_Nom-V12_Max)))*((V48_Nom-V12_Max)/(V12_Max)),1-(V12_Max/V48_Nom)) -> 0.37260001 | AL8: =IF($O8<((V48_Nom-V12_Max)*V12_Max)/((2*Lm*Fsw)*V48_Nom),(AJ8/(Fsw*Lm))*(V48_Nom-V12_Max),((AJ8/(Fsw*Lm))*(V48_Nom-V12_Max))) -> 5.1529789 | AM8: =IF($O8<((V48_Nom-V12_Max)*V12_Max)/((2*Lm*Fsw)*V48_Nom),(AJ8/(Fsw*Lm))*(V48_Nom-V12_Max),(AL8/2)+$O8) -> 5.1529789
A9: V48_Max | B9: =Design_Converter!B13 -> 85 | C9: V | E9: Maximum 48V rail Voltage | J9: Spec Values | N9: 0.003 | O9: =N9/Rcs -> 3 | P9: =IF($O9<((V48_Min-V12_Nom)*V12_Nom)/((2*Lm*Fsw)*V48_Min),SQRT((2*$O9*Lm*Fsw*V12_Nom)/(V48_Min*(V48_Min-V12_Nom))),(V12_Nom/V48_Min)) -> 0.66666667 | Q9: =IF($O9<((V48_Min-V12_Nom)*V12_Nom)/((2*Lm*Fsw)*V48_Min),SQRT((2*$O9*Lm*Fsw*V12_Nom)/(V48_Min*(V48_Min-V12_Nom)))*((V48_Min-V12_Nom)/(V12_Nom)),1-(V12_Nom/V48_Min)) -> 0.33333333 | R9: =IF($O9<((V48_Min-V12_Nom)*V12_Nom)/((2*Lm*Fsw)*V48_Min),(P9/(Fsw*Lm))*(V48_Min-V12_Nom),((P9/(Fsw*Lm))*(V48_Min-V12_Nom))) -> 3.5460993 | S9: =IF($O9<((V48_Min-V12_Nom)*V12_Nom)/((2*Lm*Fsw)*V48_Min),(P9/(Fsw*Lm))*(V48_Min-V12_Nom),(R9/2)+$O9) -> 4.7730496 | T9: =IF($O9<((V48_Nom-V12_Nom)*V12_Nom)/((2*Lm*Fsw)*V48_Nom),SQRT((2*$O9*Lm*Fsw*V12_Nom)/(V48_Nom*(V48_Nom-V12_Nom))),(V12_Nom/V48_Nom)) -> 0.38781439 | U9: =IF($O9<((V48_Nom-V12_Nom)*V12_Nom)/((2*Lm*Fsw)*V48_Nom),SQRT((2*$O9*Lm*Fsw*V12_Nom)/(V48_Nom*(V48_Nom-V12_Nom)))*((V48_Nom-V12_Nom)/(V12_Nom)),1-(V12_Nom/V48_Nom)) -> 0.58172158 | V9: =IF($O9<((V48_Nom-V12_Nom)*V12_Nom)/((2*Lm*Fsw)*V48_Nom),(T9/(Fsw*Lm))*(V48_Nom-V12_Nom),((T9/(Fsw*Lm))*(V48_Nom-V12_Nom))) -> 6.1885275 | W9: =IF($O9<((V48_Nom-V12_Nom)*V12_Nom)/((2*Lm*Fsw)*V48_Nom),(T9/(Fsw*Lm))*(V48_Nom-V12_Nom),(V9/2)+$O9) -> 6.1885275 | X9: =IF($O9<((V48_Max-V12_Nom)*V12_Nom)/((2*Lm*Fsw)*V48_Max),SQRT((2*$O9*Lm*Fsw*V12_Nom)/(V48_Max*(V48_Max-V12_Nom))),(V12_Nom/V48_Max)) -> 0.20207073 | Y9: =IF($O9<((V48_Max-V12_Nom)*V12_Nom)/((2*Lm*Fsw)*V48_Max),SQRT((2*$O9*Lm*Fsw*V12_Nom)/(V48_Max*(V48_Max-V12_Nom)))*((V48_Max-V12_Nom)/(V12_Nom)),1-(V12_Nom/V48_Max)) -> 0.65672987 | Z9: =IF($O9<((V48_Max-V12_Nom)*V12_Nom)/((2*Lm*Fsw)*V48_Max),(X9/(Fsw*Lm))*(V48_Max-V12_Nom),((X9/(Fsw*Lm))*(V48_Max-V12_Nom))) -> 6.9864879 | AA9: =IF($O9<((V48_Max-V12_Nom)*V12_Nom)/((2*Lm*Fsw)*V48_Max),(X9/(Fsw*Lm))*(V48_Max-V12_Nom),(Z9/2)+$O9) -> 6.9864879 | AB9: =IF($O9<((V48_Nom-V12_Min)*V12_Min)/((2*Lm*Fsw)*V48_Nom),SQRT((2*$O9*Lm*Fsw*V12_Min)/(V48_Nom*(V48_Nom-V12_Min))),(V12_Min/V48_Nom)) -> 0.36399895 | AC9: =IF($O9<((V48_Nom-V12_Min)*V12_Min)/((2*Lm*Fsw)*V48_Nom),SQRT((2*$O9*Lm*Fsw*V12_Min)/(V48_Nom*(V48_Nom-V12_Min)))*((V48_Nom-V12_Min)/(V12_Min)),1-(V12_Min/V48_Nom)) -> 0.619782 | AD9: =IF($O9<((V48_Nom-V12_Min)*V12_Min)/((2*Lm*Fsw)*V48_Nom),(AB9/(Fsw*Lm))*(V48_Nom-V12_Min),((AB9/(Fsw*Lm))*(V48_Nom-V12_Min))) -> 6.0989186 | AE9: =IF($O9<((V48_Nom-V12_Min)*V12_Min)/((2*Lm*Fsw)*V48_Nom),(AB9/(Fsw*Lm))*(V48_Nom-V12_Min),(AD9/2)+$O9) -> 6.0989186 | AF9: =IF($O9<((V48_Nom-V12_Nom)*V12_Nom)/((2*Lm*Fsw)*V48_Nom),SQRT((2*$O9*Lm*Fsw*V12_Nom)/(V48_Nom*(V48_Nom-V12_Nom))),(V12_Nom/V48_Nom)) -> 0.38781439 | AG9: =IF($O9<((V48_Nom-V12_Nom)*V12_Nom)/((2*Lm*Fsw)*V48_Nom),SQRT((2*$O9*Lm*Fsw*V12_Nom)/(V48_Nom*(V48_Nom-V12_Nom)))*((V48_Nom-V12_Nom)/(V12_Nom)),1-(V12_Nom/V48_Nom)) -> 0.58172158 | AH9: =IF($O9<((V48_Nom-V12_Nom)*V12_Nom)/((2*Lm*Fsw)*V48_Nom),(AF9/(Fsw*Lm))*(V48_Nom-V12_Nom),((AF9/(Fsw*Lm))*(V48_Nom-V12_Nom))) -> 6.1885275 | AI9: =IF($O9<((V48_Nom-V12_Nom)*V12_Nom)/((2*Lm*Fsw)*V48_Nom),(AF9/(Fsw*Lm))*(V48_Nom-V12_Nom),(AH9/2)+$O9) -> 6.1885275 | AJ9: =IF($O9<((V48_Nom-V12_Max)*V12_Max)/((2*Lm*Fsw)*V48_Nom),SQRT((2*$O9*Lm*Fsw*V12_Max)/(V48_Nom*(V48_Nom-V12_Max))),(V12_Max/V48_Nom)) -> 0.49436828 | AK9: =IF($O9<((V48_Nom-V12_Max)*V12_Max)/((2*Lm*Fsw)*V48_Nom),SQRT((2*$O9*Lm*Fsw*V12_Max)/(V48_Nom*(V48_Nom-V12_Max)))*((V48_Nom-V12_Max)/(V12_Max)),1-(V12_Max/V48_Nom)) -> 0.45633995 | AL9: =IF($O9<((V48_Nom-V12_Max)*V12_Max)/((2*Lm*Fsw)*V48_Nom),(AJ9/(Fsw*Lm))*(V48_Nom-V12_Max),((AJ9/(Fsw*Lm))*(V48_Nom-V12_Max))) -> 6.3110845 | AM9: =IF($O9<((V48_Nom-V12_Max)*V12_Max)/((2*Lm*Fsw)*V48_Nom),(AJ9/(Fsw*Lm))*(V48_Nom-V12_Max),(AL9/2)+$O9) -> 6.3110845
A10: V12 Rail Selection | J10: Variable | N10: 0.004 | O10: =N10/Rcs -> 4 | P10: =IF($O10<((V48_Min-V12_Nom)*V12_Nom)/((2*Lm*Fsw)*V48_Min),SQRT((2*$O10*Lm*Fsw*V12_Nom)/(V48_Min*(V48_Min-V12_Nom))),(V12_Nom/V48_Min)) -> 0.66666667 | Q10: =IF($O10<((V48_Min-V12_Nom)*V12_Nom)/((2*Lm*Fsw)*V48_Min),SQRT((2*$O10*Lm*Fsw*V12_Nom)/(V48_Min*(V48_Min-V12_Nom)))*((V48_Min-V12_Nom)/(V12_Nom)),1-(V12_Nom/V48_Min)) -> 0.33333333 | R10: =IF($O10<((V48_Min-V12_Nom)*V12_Nom)/((2*Lm*Fsw)*V48_Min),(P10/(Fsw*Lm))*(V48_Min-V12_Nom),((P10/(Fsw*Lm))*(V48_Min-V12_Nom))) -> 3.5460993 | S10: =IF($O10<((V48_Min-V12_Nom)*V12_Nom)/((2*Lm*Fsw)*V48_Min),(P10/(Fsw*Lm))*(V48_Min-V12_Nom),(R10/2)+$O10) -> 5.7730496 | T10: =IF($O10<((V48_Nom-V12_Nom)*V12_Nom)/((2*Lm*Fsw)*V48_Nom),SQRT((2*$O10*Lm*Fsw*V12_Nom)/(V48_Nom*(V48_Nom-V12_Nom))),(V12_Nom/V48_Nom)) -> 0.4 | U10: =IF($O10<((V48_Nom-V12_Nom)*V12_Nom)/((2*Lm*Fsw)*V48_Nom),SQRT((2*$O10*Lm*Fsw*V12_Nom)/(V48_Nom*(V48_Nom-V12_Nom)))*((V48_Nom-V12_Nom)/(V12_Nom)),1-(V12_Nom/V48_Nom)) -> 0.6 | V10: =IF($O10<((V48_Nom-V12_Nom)*V12_Nom)/((2*Lm*Fsw)*V48_Nom),(T10/(Fsw*Lm))*(V48_Nom-V12_Nom),((T10/(Fsw*Lm))*(V48_Nom-V12_Nom))) -> 6.3829787 | W10: =IF($O10<((V48_Nom-V12_Nom)*V12_Nom)/((2*Lm*Fsw)*V48_Nom),(T10/(Fsw*Lm))*(V48_Nom-V12_Nom),(V10/2)+$O10) -> 7.1914894 | X10: =IF($O10<((V48_Max-V12_Nom)*V12_Nom)/((2*Lm*Fsw)*V48_Max),SQRT((2*$O10*Lm*Fsw*V12_Nom)/(V48_Max*(V48_Max-V12_Nom))),(V12_Nom/V48_Max)) -> 0.23333118 | Y10: =IF($O10<((V48_Max-V12_Nom)*V12_Nom)/((2*Lm*Fsw)*V48_Max),SQRT((2*$O10*Lm*Fsw*V12_Nom)/(V48_Max*(V48_Max-V12_Nom)))*((V48_Max-V12_Nom)/(V12_Nom)),1-(V12_Nom/V48_Max)) -> 0.75832633 | Z10: =IF($O10<((V48_Max-V12_Nom)*V12_Nom)/((2*Lm*Fsw)*V48_Max),(X10/(Fsw*Lm))*(V48_Max-V12_Nom),((X10/(Fsw*Lm))*(V48_Max-V12_Nom))) -> 8.0673014 | AA10: =IF($O10<((V48_Max-V12_Nom)*V12_Nom)/((2*Lm*Fsw)*V48_Max),(X10/(Fsw*Lm))*(V48_Max-V12_Nom),(Z10/2)+$O10) -> 8.0673014 | AB10: =IF($O10<((V48_Nom-V12_Min)*V12_Min)/((2*Lm*Fsw)*V48_Nom),SQRT((2*$O10*Lm*Fsw*V12_Min)/(V48_Nom*(V48_Nom-V12_Min))),(V12_Min/V48_Nom)) -> 0.37 | AC10: =IF($O10<((V48_Nom-V12_Min)*V12_Min)/((2*Lm*Fsw)*V48_Nom),SQRT((2*$O10*Lm*Fsw*V12_Min)/(V48_Nom*(V48_Nom-V12_Min)))*((V48_Nom-V12_Min)/(V12_Min)),1-(V12_Min/V48_Nom)) -> 0.63 | AD10: =IF($O10<((V48_Nom-V12_Min)*V12_Min)/((2*Lm*Fsw)*V48_Nom),(AB10/(Fsw*Lm))*(V48_Nom-V12_Min),((AB10/(Fsw*Lm))*(V48_Nom-V12_Min))) -> 6.1994681 | AE10: =IF($O10<((V48_Nom-V12_Min)*V12_Min)/((2*Lm*Fsw)*V48_Nom),(AB10/(Fsw*Lm))*(V48_Nom-V12_Min),(AD10/2)+$O10) -> 7.099734 | AF10: =IF($O10<((V48_Nom-V12_Nom)*V12_Nom)/((2*Lm*Fsw)*V48_Nom),SQRT((2*$O10*Lm*Fsw*V12_Nom)/(V48_Nom*(V48_Nom-V12_Nom))),(V12_Nom/V48_Nom)) -> 0.4 | AG10: =IF($O10<((V48_Nom-V12_Nom)*V12_Nom)/((2*Lm*Fsw)*V48_Nom),SQRT((2*$O10*Lm*Fsw*V12_Nom)/(V48_Nom*(V48_Nom-V12_Nom)))*((V48_Nom-V12_Nom)/(V12_Nom)),1-(V12_Nom/V48_Nom)) -> 0.6 | AH10: =IF($O10<((V48_Nom-V12_Nom)*V12_Nom)/((2*Lm*Fsw)*V48_Nom),(AF10/(Fsw*Lm))*(V48_Nom-V12_Nom),((AF10/(Fsw*Lm))*(V48_Nom-V12_Nom))) -> 6.3829787 | AI10: =IF($O10<((V48_Nom-V12_Nom)*V12_Nom)/((2*Lm*Fsw)*V48_Nom),(AF10/(Fsw*Lm))*(V48_Nom-V12_Nom),(AH10/2)+$O10) -> 7.1914894 | AJ10: =IF($O10<((V48_Nom-V12_Max)*V12_Max)/((2*Lm*Fsw)*V48_Nom),SQRT((2*$O10*Lm*Fsw*V12_Max)/(V48_Nom*(V48_Nom-V12_Max))),(V12_Max/V48_Nom)) -> 0.52 | AK10: =IF($O10<((V48_Nom-V12_Max)*V12_Max)/((2*Lm*Fsw)*V48_Nom),SQRT((2*$O10*Lm*Fsw*V12_Max)/(V48_Nom*(V48_Nom-V12_Max)))*((V48_Nom-V12_Max)/(V12_Max)),1-(V12_Max/V48_Nom)) -> 0.48 | AL10: =IF($O10<((V48_Nom-V12_Max)*V12_Max)/((2*Lm*Fsw)*V48_Nom),(AJ10/(Fsw*Lm))*(V48_Nom-V12_Max),((AJ10/(Fsw*Lm))*(V48_Nom-V12_Max))) -> 6.6382979 | AM10: =IF($O10<((V48_Nom-V12_Max)*V12_Max)/((2*Lm*Fsw)*V48_Nom),(AJ10/(Fsw*Lm))*(V48_Nom-V12_Max),(AL10/2)+$O10) -> 7.3191489
A11: V12_Min | B11: =Design_Converter!B16 -> 18.5 | C11: V | E11: Minimum 12V Rail Voltage | N11: 0.005 | O11: =N11/Rcs -> 5 | P11: =IF($O11<((V48_Min-V12_Nom)*V12_Nom)/((2*Lm*Fsw)*V48_Min),SQRT((2*$O11*Lm*Fsw*V12_Nom)/(V48_Min*(V48_Min-V12_Nom))),(V12_Nom/V48_Min)) -> 0.66666667 | Q11: =IF($O11<((V48_Min-V12_Nom)*V12_Nom)/((2*Lm*Fsw)*V48_Min),SQRT((2*$O11*Lm*Fsw*V12_Nom)/(V48_Min*(V48_Min-V12_Nom)))*((V48_Min-V12_Nom)/(V12_Nom)),1-(V12_Nom/V48_Min)) -> 0.33333333 | R11: =IF($O11<((V48_Min-V12_Nom)*V12_Nom)/((2*Lm*Fsw)*V48_Min),(P11/(Fsw*Lm))*(V48_Min-V12_Nom),((P11/(Fsw*Lm))*(V48_Min-V12_Nom))) -> 3.5460993 | S11: =IF($O11<((V48_Min-V12_Nom)*V12_Nom)/((2*Lm*Fsw)*V48_Min),(P11/(Fsw*Lm))*(V48_Min-V12_Nom),(R11/2)+$O11) -> 6.7730496 | T11: =IF($O11<((V48_Nom-V12_Nom)*V12_Nom)/((2*Lm*Fsw)*V48_Nom),SQRT((2*$O11*Lm*Fsw*V12_Nom)/(V48_Nom*(V48_Nom-V12_Nom))),(V12_Nom/V48_Nom)) -> 0.4 | U11: =IF($O11<((V48_Nom-V12_Nom)*V12_Nom)/((2*Lm*Fsw)*V48_Nom),SQRT((2*$O11*Lm*Fsw*V12_Nom)/(V48_Nom*(V48_Nom-V12_Nom)))*((V48_Nom-V12_Nom)/(V12_Nom)),1-(V12_Nom/V48_Nom)) -> 0.6 | V11: =IF($O11<((V48_Nom-V12_Nom)*V12_Nom)/((2*Lm*Fsw)*V48_Nom),(T11/(Fsw*Lm))*(V48_Nom-V12_Nom),((T11/(Fsw*Lm))*(V48_Nom-V12_Nom))) -> 6.3829787 | W11: =IF($O11<((V48_Nom-V12_Nom)*V12_Nom)/((2*Lm*Fsw)*V48_Nom),(T11/(Fsw*Lm))*(V48_Nom-V12_Nom),(V11/2)+$O11) -> 8.1914894 | X11: =IF($O11<((V48_Max-V12_Nom)*V12_Nom)/((2*Lm*Fsw)*V48_Max),SQRT((2*$O11*Lm*Fsw*V12_Nom)/(V48_Max*(V48_Max-V12_Nom))),(V12_Nom/V48_Max)) -> 0.23529412 | Y11: =IF($O11<((V48_Max-V12_Nom)*V12_Nom)/((2*Lm*Fsw)*V48_Max),SQRT((2*$O11*Lm*Fsw*V12_Nom)/(V48_Max*(V48_Max-V12_Nom)))*((V48_Max-V12_Nom)/(V12_Nom)),1-(V12_Nom/V48_Max)) -> 0.76470588 | Z11: =IF($O11<((V48_Max-V12_Nom)*V12_Nom)/((2*Lm*Fsw)*V48_Max),(X11/(Fsw*Lm))*(V48_Max-V12_Nom),((X11/(Fsw*Lm))*(V48_Max-V12_Nom))) -> 8.135169 | AA11: =IF($O11<((V48_Max-V12_Nom)*V12_Nom)/((2*Lm*Fsw)*V48_Max),(X11/(Fsw*Lm))*(V48_Max-V12_Nom),(Z11/2)+$O11) -> 9.0675845 | AB11: =IF($O11<((V48_Nom-V12_Min)*V12_Min)/((2*Lm*Fsw)*V48_Nom),SQRT((2*$O11*Lm*Fsw*V12_Min)/(V48_Nom*(V48_Nom-V12_Min))),(V12_Min/V48_Nom)) -> 0.37 | AC11: =IF($O11<((V48_Nom-V12_Min)*V12_Min)/((2*Lm*Fsw)*V48_Nom),SQRT((2*$O11*Lm*Fsw*V12_Min)/(V48_Nom*(V48_Nom-V12_Min)))*((V48_Nom-V12_Min)/(V12_Min)),1-(V12_Min/V48_Nom)) -> 0.63 | AD11: =IF($O11<((V48_Nom-V12_Min)*V12_Min)/((2*Lm*Fsw)*V48_Nom),(AB11/(Fsw*Lm))*(V48_Nom-V12_Min),((AB11/(Fsw*Lm))*(V48_Nom-V12_Min))) -> 6.1994681 | AE11: =IF($O11<((V48_Nom-V12_Min)*V12_Min)/((2*Lm*Fsw)*V48_Nom),(AB11/(Fsw*Lm))*(V48_Nom-V12_Min),(AD11/2)+$O11) -> 8.099734 | AF11: =IF($O11<((V48_Nom-V12_Nom)*V12_Nom)/((2*Lm*Fsw)*V48_Nom),SQRT((2*$O11*Lm*Fsw*V12_Nom)/(V48_Nom*(V48_Nom-V12_Nom))),(V12_Nom/V48_Nom)) -> 0.4 | AG11: =IF($O11<((V48_Nom-V12_Nom)*V12_Nom)/((2*Lm*Fsw)*V48_Nom),SQRT((2*$O11*Lm*Fsw*V12_Nom)/(V48_Nom*(V48_Nom-V12_Nom)))*((V48_Nom-V12_Nom)/(V12_Nom)),1-(V12_Nom/V48_Nom)) -> 0.6 | AH11: =IF($O11<((V48_Nom-V12_Nom)*V12_Nom)/((2*Lm*Fsw)*V48_Nom),(AF11/(Fsw*Lm))*(V48_Nom-V12_Nom),((AF11/(Fsw*Lm))*(V48_Nom-V12_Nom))) -> 6.3829787 | AI11: =IF($O11<((V48_Nom-V12_Nom)*V12_Nom)/((2*Lm*Fsw)*V48_Nom),(AF11/(Fsw*Lm))*(V48_Nom-V12_Nom),(AH11/2)+$O11) -> 8.1914894 | AJ11: =IF($O11<((V48_Nom-V12_Max)*V12_Max)/((2*Lm*Fsw)*V48_Nom),SQRT((2*$O11*Lm*Fsw*V12_Max)/(V48_Nom*(V48_Nom-V12_Max))),(V12_Max/V48_Nom)) -> 0.52 | AK11: =IF($O11<((V48_Nom-V12_Max)*V12_Max)/((2*Lm*Fsw)*V48_Nom),SQRT((2*$O11*Lm*Fsw*V12_Max)/(V48_Nom*(V48_Nom-V12_Max)))*((V48_Nom-V12_Max)/(V12_Max)),1-(V12_Max/V48_Nom)) -> 0.48 | AL11: =IF($O11<((V48_Nom-V12_Max)*V12_Max)/((2*Lm*Fsw)*V48_Nom),(AJ11/(Fsw*Lm))*(V48_Nom-V12_Max),((AJ11/(Fsw*Lm))*(V48_Nom-V12_Max))) -> 6.6382979 | AM11: =IF($O11<((V48_Nom-V12_Max)*V12_Max)/((2*Lm*Fsw)*V48_Nom),(AJ11/(Fsw*Lm))*(V48_Nom-V12_Max),(AL11/2)+$O11) -> 8.3191489
A12: V12_Nom | B12: =Design_Converter!B17 -> 20 | C12: V | E12: Nominal 12V Rail Voltage | N12: 0.006 | O12: =N12/Rcs -> 6 | P12: =IF($O12<((V48_Min-V12_Nom)*V12_Nom)/((2*Lm*Fsw)*V48_Min),SQRT((2*$O12*Lm*Fsw*V12_Nom)/(V48_Min*(V48_Min-V12_Nom))),(V12_Nom/V48_Min)) -> 0.66666667 | Q12: =IF($O12<((V48_Min-V12_Nom)*V12_Nom)/((2*Lm*Fsw)*V48_Min),SQRT((2*$O12*Lm*Fsw*V12_Nom)/(V48_Min*(V48_Min-V12_Nom)))*((V48_Min-V12_Nom)/(V12_Nom)),1-(V12_Nom/V48_Min)) -> 0.33333333 | R12: =IF($O12<((V48_Min-V12_Nom)*V12_Nom)/((2*Lm*Fsw)*V48_Min),(P12/(Fsw*Lm))*(V48_Min-V12_Nom),((P12/(Fsw*Lm))*(V48_Min-V12_Nom))) -> 3.5460993 | S12: =IF($O12<((V48_Min-V12_Nom)*V12_Nom)/((2*Lm*Fsw)*V48_Min),(P12/(Fsw*Lm))*(V48_Min-V12_Nom),(R12/2)+$O12) -> 7.7730496 | T12: =IF($O12<((V48_Nom-V12_Nom)*V12_Nom)/((2*Lm*Fsw)*V48_Nom),SQRT((2*$O12*Lm*Fsw*V12_Nom)/(V48_Nom*(V48_Nom-V12_Nom))),(V12_Nom/V48_Nom)) -> 0.4 | U12: =IF($O12<((V48_Nom-V12_Nom)*V12_Nom)/((2*Lm*Fsw)*V48_Nom),SQRT((2*$O12*Lm*Fsw*V12_Nom)/(V48_Nom*(V48_Nom-V12_Nom)))*((V48_Nom-V12_Nom)/(V12_Nom)),1-(V12_Nom/V48_Nom)) -> 0.6 | V12: =IF($O12<((V48_Nom-V12_Nom)*V12_Nom)/((2*Lm*Fsw)*V48_Nom),(T12/(Fsw*Lm))*(V48_Nom-V12_Nom),((T12/(Fsw*Lm))*(V48_Nom-V12_Nom))) -> 6.3829787 | W12: =IF($O12<((V48_Nom-V12_Nom)*V12_Nom)/((2*Lm*Fsw)*V48_Nom),(T12/(Fsw*Lm))*(V48_Nom-V12_Nom),(V12/2)+$O12) -> 9.1914894 | X12: =IF($O12<((V48_Max-V12_Nom)*V12_Nom)/((2*Lm*Fsw)*V48_Max),SQRT((2*$O12*Lm*Fsw*V12_Nom)/(V48_Max*(V48_Max-V12_Nom))),(V12_Nom/V48_Max)) -> 0.23529412 | Y12: =IF($O12<((V48_Max-V12_Nom)*V12_Nom)/((2*Lm*Fsw)*V48_Max),SQRT((2*$O12*Lm*Fsw*V12_Nom)/(V48_Max*(V48_Max-V12_Nom)))*((V48_Max-V12_Nom)/(V12_Nom)),1-(V12_Nom/V48_Max)) -> 0.76470588 | Z12: =IF($O12<((V48_Max-V12_Nom)*V12_Nom)/((2*Lm*Fsw)*V48_Max),(X12/(Fsw*Lm))*(V48_Max-V12_Nom),((X12/(Fsw*Lm))*(V48_Max-V12_Nom))) -> 8.135169 | AA12: =IF($O12<((V48_Max-V12_Nom)*V12_Nom)/((2*Lm*Fsw)*V48_Max),(X12/(Fsw*Lm))*(V48_Max-V12_Nom),(Z12/2)+$O12) -> 10.067584 | AB12: =IF($O12<((V48_Nom-V12_Min)*V12_Min)/((2*Lm*Fsw)*V48_Nom),SQRT((2*$O12*Lm*Fsw*V12_Min)/(V48_Nom*(V48_Nom-V12_Min))),(V12_Min/V48_Nom)) -> 0.37 | AC12: =IF($O12<((V48_Nom-V12_Min)*V12_Min)/((2*Lm*Fsw)*V48_Nom),SQRT((2*$O12*Lm*Fsw*V12_Min)/(V48_Nom*(V48_Nom-V12_Min)))*((V48_Nom-V12_Min)/(V12_Min)),1-(V12_Min/V48_Nom)) -> 0.63 | AD12: =IF($O12<((V48_Nom-V12_Min)*V12_Min)/((2*Lm*Fsw)*V48_Nom),(AB12/(Fsw*Lm))*(V48_Nom-V12_Min),((AB12/(Fsw*Lm))*(V48_Nom-V12_Min))) -> 6.1994681 | AE12: =IF($O12<((V48_Nom-V12_Min)*V12_Min)/((2*Lm*Fsw)*V48_Nom),(AB12/(Fsw*Lm))*(V48_Nom-V12_Min),(AD12/2)+$O12) -> 9.099734 | AF12: =IF($O12<((V48_Nom-V12_Nom)*V12_Nom)/((2*Lm*Fsw)*V48_Nom),SQRT((2*$O12*Lm*Fsw*V12_Nom)/(V48_Nom*(V48_Nom-V12_Nom))),(V12_Nom/V48_Nom)) -> 0.4 | AG12: =IF($O12<((V48_Nom-V12_Nom)*V12_Nom)/((2*Lm*Fsw)*V48_Nom),SQRT((2*$O12*Lm*Fsw*V12_Nom)/(V48_Nom*(V48_Nom-V12_Nom)))*((V48_Nom-V12_Nom)/(V12_Nom)),1-(V12_Nom/V48_Nom)) -> 0.6 | AH12: =IF($O12<((V48_Nom-V12_Nom)*V12_Nom)/((2*Lm*Fsw)*V48_Nom),(AF12/(Fsw*Lm))*(V48_Nom-V12_Nom),((AF12/(Fsw*Lm))*(V48_Nom-V12_Nom))) -> 6.3829787 | AI12: =IF($O12<((V48_Nom-V12_Nom)*V12_Nom)/((2*Lm*Fsw)*V48_Nom),(AF12/(Fsw*Lm))*(V48_Nom-V12_Nom),(AH12/2)+$O12) -> 9.1914894 | AJ12: =IF($O12<((V48_Nom-V12_Max)*V12_Max)/((2*Lm*Fsw)*V48_Nom),SQRT((2*$O12*Lm*Fsw*V12_Max)/(V48_Nom*(V48_Nom-V12_Max))),(V12_Max/V48_Nom)) -> 0.52 | AK12: =IF($O12<((V48_Nom-V12_Max)*V12_Max)/((2*Lm*Fsw)*V48_Nom),SQRT((2*$O12*Lm*Fsw*V12_Max)/(V48_Nom*(V48_Nom-V12_Max)))*((V48_Nom-V12_Max)/(V12_Max)),1-(V12_Max/V48_Nom)) -> 0.48 | AL12: =IF($O12<((V48_Nom-V12_Max)*V12_Max)/((2*Lm*Fsw)*V48_Nom),(AJ12/(Fsw*Lm))*(V48_Nom-V12_Max),((AJ12/(Fsw*Lm))*(V48_Nom-V12_Max))) -> 6.6382979 | AM12: =IF($O12<((V48_Nom-V12_Max)*V12_Max)/((2*Lm*Fsw)*V48_Nom),(AJ12/(Fsw*Lm))*(V48_Nom-V12_Max),(AL12/2)+$O12) -> 9.3191489
A13: V12_Max | B13: =Design_Converter!B18 -> 26 | C13: V | E13: Maximum 12V rail Voltage | N13: 0.007 | O13: =N13/Rcs -> 7 | P13: =IF($O13<((V48_Min-V12_Nom)*V12_Nom)/((2*Lm*Fsw)*V48_Min),SQRT((2*$O13*Lm*Fsw*V12_Nom)/(V48_Min*(V48_Min-V12_Nom))),(V12_Nom/V48_Min)) -> 0.66666667 | Q13: =IF($O13<((V48_Min-V12_Nom)*V12_Nom)/((2*Lm*Fsw)*V48_Min),SQRT((2*$O13*Lm*Fsw*V12_Nom)/(V48_Min*(V48_Min-V12_Nom)))*((V48_Min-V12_Nom)/(V12_Nom)),1-(V12_Nom/V48_Min)) -> 0.33333333 | R13: =IF($O13<((V48_Min-V12_Nom)*V12_Nom)/((2*Lm*Fsw)*V48_Min),(P13/(Fsw*Lm))*(V48_Min-V12_Nom),((P13/(Fsw*Lm))*(V48_Min-V12_Nom))) -> 3.5460993 | S13: =IF($O13<((V48_Min-V12_Nom)*V12_Nom)/((2*Lm*Fsw)*V48_Min),(P13/(Fsw*Lm))*(V48_Min-V12_Nom),(R13/2)+$O13) -> 8.7730496 | T13: =IF($O13<((V48_Nom-V12_Nom)*V12_Nom)/((2*Lm*Fsw)*V48_Nom),SQRT((2*$O13*Lm*Fsw*V12_Nom)/(V48_Nom*(V48_Nom-V12_Nom))),(V12_Nom/V48_Nom)) -> 0.4 | U13: =IF($O13<((V48_Nom-V12_Nom)*V12_Nom)/((2*Lm*Fsw)*V48_Nom),SQRT((2*$O13*Lm*Fsw*V12_Nom)/(V48_Nom*(V48_Nom-V12_Nom)))*((V48_Nom-V12_Nom)/(V12_Nom)),1-(V12_Nom/V48_Nom)) -> 0.6 | V13: =IF($O13<((V48_Nom-V12_Nom)*V12_Nom)/((2*Lm*Fsw)*V48_Nom),(T13/(Fsw*Lm))*(V48_Nom-V12_Nom),((T13/(Fsw*Lm))*(V48_Nom-V12_Nom))) -> 6.3829787 | W13: =IF($O13<((V48_Nom-V12_Nom)*V12_Nom)/((2*Lm*Fsw)*V48_Nom),(T13/(Fsw*Lm))*(V48_Nom-V12_Nom),(V13/2)+$O13) -> 10.191489 | X13: =IF($O13<((V48_Max-V12_Nom)*V12_Nom)/((2*Lm*Fsw)*V48_Max),SQRT((2*$O13*Lm*Fsw*V12_Nom)/(V48_Max*(V48_Max-V12_Nom))),(V12_Nom/V48_Max)) -> 0.23529412 | Y13: =IF($O13<((V48_Max-V12_Nom)*V12_Nom)/((2*Lm*Fsw)*V48_Max),SQRT((2*$O13*Lm*Fsw*V12_Nom)/(V48_Max*(V48_Max-V12_Nom)))*((V48_Max-V12_Nom)/(V12_Nom)),1-(V12_Nom/V48_Max)) -> 0.76470588 | Z13: =IF($O13<((V48_Max-V12_Nom)*V12_Nom)/((2*Lm*Fsw)*V48_Max),(X13/(Fsw*Lm))*(V48_Max-V12_Nom),((X13/(Fsw*Lm))*(V48_Max-V12_Nom))) -> 8.135169 | AA13: =IF($O13<((V48_Max-V12_Nom)*V12_Nom)/((2*Lm*Fsw)*V48_Max),(X13/(Fsw*Lm))*(V48_Max-V12_Nom),(Z13/2)+$O13) -> 11.067584 | AB13: =IF($O13<((V48_Nom-V12_Min)*V12_Min)/((2*Lm*Fsw)*V48_Nom),SQRT((2*$O13*Lm*Fsw*V12_Min)/(V48_Nom*(V48_Nom-V12_Min))),(V12_Min/V48_Nom)) -> 0.37 | AC13: =IF($O13<((V48_Nom-V12_Min)*V12_Min)/((2*Lm*Fsw)*V48_Nom),SQRT((2*$O13*Lm*Fsw*V12_Min)/(V48_Nom*(V48_Nom-V12_Min)))*((V48_Nom-V12_Min)/(V12_Min)),1-(V12_Min/V48_Nom)) -> 0.63 | AD13: =IF($O13<((V48_Nom-V12_Min)*V12_Min)/((2*Lm*Fsw)*V48_Nom),(AB13/(Fsw*Lm))*(V48_Nom-V12_Min),((AB13/(Fsw*Lm))*(V48_Nom-V12_Min))) -> 6.1994681 | AE13: =IF($O13<((V48_Nom-V12_Min)*V12_Min)/((2*Lm*Fsw)*V48_Nom),(AB13/(Fsw*Lm))*(V48_Nom-V12_Min),(AD13/2)+$O13) -> 10.099734 | AF13: =IF($O13<((V48_Nom-V12_Nom)*V12_Nom)/((2*Lm*Fsw)*V48_Nom),SQRT((2*$O13*Lm*Fsw*V12_Nom)/(V48_Nom*(V48_Nom-V12_Nom))),(V12_Nom/V48_Nom)) -> 0.4 | AG13: =IF($O13<((V48_Nom-V12_Nom)*V12_Nom)/((2*Lm*Fsw)*V48_Nom),SQRT((2*$O13*Lm*Fsw*V12_Nom)/(V48_Nom*(V48_Nom-V12_Nom)))*((V48_Nom-V12_Nom)/(V12_Nom)),1-(V12_Nom/V48_Nom)) -> 0.6 | AH13: =IF($O13<((V48_Nom-V12_Nom)*V12_Nom)/((2*Lm*Fsw)*V48_Nom),(AF13/(Fsw*Lm))*(V48_Nom-V12_Nom),((AF13/(Fsw*Lm))*(V48_Nom-V12_Nom))) -> 6.3829787 | AI13: =IF($O13<((V48_Nom-V12_Nom)*V12_Nom)/((2*Lm*Fsw)*V48_Nom),(AF13/(Fsw*Lm))*(V48_Nom-V12_Nom),(AH13/2)+$O13) -> 10.191489 | AJ13: =IF($O13<((V48_Nom-V12_Max)*V12_Max)/((2*Lm*Fsw)*V48_Nom),SQRT((2*$O13*Lm*Fsw*V12_Max)/(V48_Nom*(V48_Nom-V12_Max))),(V12_Max/V48_Nom)) -> 0.52 | AK13: =IF($O13<((V48_Nom-V12_Max)*V12_Max)/((2*Lm*Fsw)*V48_Nom),SQRT((2*$O13*Lm*Fsw*V12_Max)/(V48_Nom*(V48_Nom-V12_Max)))*((V48_Nom-V12_Max)/(V12_Max)),1-(V12_Max/V48_Nom)) -> 0.48 | AL13: =IF($O13<((V48_Nom-V12_Max)*V12_Max)/((2*Lm*Fsw)*V48_Nom),(AJ13/(Fsw*Lm))*(V48_Nom-V12_Max),((AJ13/(Fsw*Lm))*(V48_Nom-V12_Max))) -> 6.6382979 | AM13: =IF($O13<((V48_Nom-V12_Max)*V12_Max)/((2*Lm*Fsw)*V48_Nom),(AJ13/(Fsw*Lm))*(V48_Nom-V12_Max),(AL13/2)+$O13) -> 10.319149
A14: Switching Parameters | N14: 0.008 | O14: =N14/Rcs -> 8 | P14: =IF($O14<((V48_Min-V12_Nom)*V12_Nom)/((2*Lm*Fsw)*V48_Min),SQRT((2*$O14*Lm*Fsw*V12_Nom)/(V48_Min*(V48_Min-V12_Nom))),(V12_Nom/V48_Min)) -> 0.66666667 | Q14: =IF($O14<((V48_Min-V12_Nom)*V12_Nom)/((2*Lm*Fsw)*V48_Min),SQRT((2*$O14*Lm*Fsw*V12_Nom)/(V48_Min*(V48_Min-V12_Nom)))*((V48_Min-V12_Nom)/(V12_Nom)),1-(V12_Nom/V48_Min)) -> 0.33333333 | R14: =IF($O14<((V48_Min-V12_Nom)*V12_Nom)/((2*Lm*Fsw)*V48_Min),(P14/(Fsw*Lm))*(V48_Min-V12_Nom),((P14/(Fsw*Lm))*(V48_Min-V12_Nom))) -> 3.5460993 | S14: =IF($O14<((V48_Min-V12_Nom)*V12_Nom)/((2*Lm*Fsw)*V48_Min),(P14/(Fsw*Lm))*(V48_Min-V12_Nom),(R14/2)+$O14) -> 9.7730496 | T14: =IF($O14<((V48_Nom-V12_Nom)*V12_Nom)/((2*Lm*Fsw)*V48_Nom),SQRT((2*$O14*Lm*Fsw*V12_Nom)/(V48_Nom*(V48_Nom-V12_Nom))),(V12_Nom/V48_Nom)) -> 0.4 | U14: =IF($O14<((V48_Nom-V12_Nom)*V12_Nom)/((2*Lm*Fsw)*V48_Nom),SQRT((2*$O14*Lm*Fsw*V12_Nom)/(V48_Nom*(V48_Nom-V12_Nom)))*((V48_Nom-V12_Nom)/(V12_Nom)),1-(V12_Nom/V48_Nom)) -> 0.6 | V14: =IF($O14<((V48_Nom-V12_Nom)*V12_Nom)/((2*Lm*Fsw)*V48_Nom),(T14/(Fsw*Lm))*(V48_Nom-V12_Nom),((T14/(Fsw*Lm))*(V48_Nom-V12_Nom))) -> 6.3829787 | W14: =IF($O14<((V48_Nom-V12_Nom)*V12_Nom)/((2*Lm*Fsw)*V48_Nom),(T14/(Fsw*Lm))*(V48_Nom-V12_Nom),(V14/2)+$O14) -> 11.191489 | X14: =IF($O14<((V48_Max-V12_Nom)*V12_Nom)/((2*Lm*Fsw)*V48_Max),SQRT((2*$O14*Lm*Fsw*V12_Nom)/(V48_Max*(V48_Max-V12_Nom))),(V12_Nom/V48_Max)) -> 0.23529412 | Y14: =IF($O14<((V48_Max-V12_Nom)*V12_Nom)/((2*Lm*Fsw)*V48_Max),SQRT((2*$O14*Lm*Fsw*V12_Nom)/(V48_Max*(V48_Max-V12_Nom)))*((V48_Max-V12_Nom)/(V12_Nom)),1-(V12_Nom/V48_Max)) -> 0.76470588 | Z14: =IF($O14<((V48_Max-V12_Nom)*V12_Nom)/((2*Lm*Fsw)*V48_Max),(X14/(Fsw*Lm))*(V48_Max-V12_Nom),((X14/(Fsw*Lm))*(V48_Max-V12_Nom))) -> 8.135169 | AA14: =IF($O14<((V48_Max-V12_Nom)*V12_Nom)/((2*Lm*Fsw)*V48_Max),(X14/(Fsw*Lm))*(V48_Max-V12_Nom),(Z14/2)+$O14) -> 12.067584 | AB14: =IF($O14<((V48_Nom-V12_Min)*V12_Min)/((2*Lm*Fsw)*V48_Nom),SQRT((2*$O14*Lm*Fsw*V12_Min)/(V48_Nom*(V48_Nom-V12_Min))),(V12_Min/V48_Nom)) -> 0.37 | AC14: =IF($O14<((V48_Nom-V12_Min)*V12_Min)/((2*Lm*Fsw)*V48_Nom),SQRT((2*$O14*Lm*Fsw*V12_Min)/(V48_Nom*(V48_Nom-V12_Min)))*((V48_Nom-V12_Min)/(V12_Min)),1-(V12_Min/V48_Nom)) -> 0.63 | AD14: =IF($O14<((V48_Nom-V12_Min)*V12_Min)/((2*Lm*Fsw)*V48_Nom),(AB14/(Fsw*Lm))*(V48_Nom-V12_Min),((AB14/(Fsw*Lm))*(V48_Nom-V12_Min))) -> 6.1994681 | AE14: =IF($O14<((V48_Nom-V12_Min)*V12_Min)/((2*Lm*Fsw)*V48_Nom),(AB14/(Fsw*Lm))*(V48_Nom-V12_Min),(AD14/2)+$O14) -> 11.099734 | AF14: =IF($O14<((V48_Nom-V12_Nom)*V12_Nom)/((2*Lm*Fsw)*V48_Nom),SQRT((2*$O14*Lm*Fsw*V12_Nom)/(V48_Nom*(V48_Nom-V12_Nom))),(V12_Nom/V48_Nom)) -> 0.4 | AG14: =IF($O14<((V48_Nom-V12_Nom)*V12_Nom)/((2*Lm*Fsw)*V48_Nom),SQRT((2*$O14*Lm*Fsw*V12_Nom)/(V48_Nom*(V48_Nom-V12_Nom)))*((V48_Nom-V12_Nom)/(V12_Nom)),1-(V12_Nom/V48_Nom)) -> 0.6 | AH14: =IF($O14<((V48_Nom-V12_Nom)*V12_Nom)/((2*Lm*Fsw)*V48_Nom),(AF14/(Fsw*Lm))*(V48_Nom-V12_Nom),((AF14/(Fsw*Lm))*(V48_Nom-V12_Nom))) -> 6.3829787 | AI14: =IF($O14<((V48_Nom-V12_Nom)*V12_Nom)/((2*Lm*Fsw)*V48_Nom),(AF14/(Fsw*Lm))*(V48_Nom-V12_Nom),(AH14/2)+$O14) -> 11.191489 | AJ14: =IF($O14<((V48_Nom-V12_Max)*V12_Max)/((2*Lm*Fsw)*V48_Nom),SQRT((2*$O14*Lm*Fsw*V12_Max)/(V48_Nom*(V48_Nom-V12_Max))),(V12_Max/V48_Nom)) -> 0.52 | AK14: =IF($O14<((V48_Nom-V12_Max)*V12_Max)/((2*Lm*Fsw)*V48_Nom),SQRT((2*$O14*Lm*Fsw*V12_Max)/(V48_Nom*(V48_Nom-V12_Max)))*((V48_Nom-V12_Max)/(V12_Max)),1-(V12_Max/V48_Nom)) -> 0.48 | AL14: =IF($O14<((V48_Nom-V12_Max)*V12_Max)/((2*Lm*Fsw)*V48_Nom),(AJ14/(Fsw*Lm))*(V48_Nom-V12_Max),((AJ14/(Fsw*Lm))*(V48_Nom-V12_Max))) -> 6.6382979 | AM14: =IF($O14<((V48_Nom-V12_Max)*V12_Max)/((2*Lm*Fsw)*V48_Nom),(AJ14/(Fsw*Lm))*(V48_Nom-V12_Max),(AL14/2)+$O14) -> 11.319149
A15: Fsw | B15: =Design_Converter!B21*1000 -> 400000 | C15: Hz | D15: =IF(AND(B15<=Constants!B39,B15<=Constants!D39),1,0) -> 0 | E15: Converter switching frequency | N15: 0.009 | O15: =N15/Rcs -> 9 | P15: =IF($O15<((V48_Min-V12_Nom)*V12_Nom)/((2*Lm*Fsw)*V48_Min),SQRT((2*$O15*Lm*Fsw*V12_Nom)/(V48_Min*(V48_Min-V12_Nom))),(V12_Nom/V48_Min)) -> 0.66666667 | Q15: =IF($O15<((V48_Min-V12_Nom)*V12_Nom)/((2*Lm*Fsw)*V48_Min),SQRT((2*$O15*Lm*Fsw*V12_Nom)/(V48_Min*(V48_Min-V12_Nom)))*((V48_Min-V12_Nom)/(V12_Nom)),1-(V12_Nom/V48_Min)) -> 0.33333333 | R15: =IF($O15<((V48_Min-V12_Nom)*V12_Nom)/((2*Lm*Fsw)*V48_Min),(P15/(Fsw*Lm))*(V48_Min-V12_Nom),((P15/(Fsw*Lm))*(V48_Min-V12_Nom))) -> 3.5460993 | S15: =IF($O15<((V48_Min-V12_Nom)*V12_Nom)/((2*Lm*Fsw)*V48_Min),(P15/(Fsw*Lm))*(V48_Min-V12_Nom),(R15/2)+$O15) -> 10.77305 | T15: =IF($O15<((V48_Nom-V12_Nom)*V12_Nom)/((2*Lm*Fsw)*V48_Nom),SQRT((2*$O15*Lm*Fsw*V12_Nom)/(V48_Nom*(V48_Nom-V12_Nom))),(V12_Nom/V48_Nom)) -> 0.4 | U15: =IF($O15<((V48_Nom-V12_Nom)*V12_Nom)/((2*Lm*Fsw)*V48_Nom),SQRT((2*$O15*Lm*Fsw*V12_Nom)/(V48_Nom*(V48_Nom-V12_Nom)))*((V48_Nom-V12_Nom)/(V12_Nom)),1-(V12_Nom/V48_Nom)) -> 0.6 | V15: =IF($O15<((V48_Nom-V12_Nom)*V12_Nom)/((2*Lm*Fsw)*V48_Nom),(T15/(Fsw*Lm))*(V48_Nom-V12_Nom),((T15/(Fsw*Lm))*(V48_Nom-V12_Nom))) -> 6.3829787 | W15: =IF($O15<((V48_Nom-V12_Nom)*V12_Nom)/((2*Lm*Fsw)*V48_Nom),(T15/(Fsw*Lm))*(V48_Nom-V12_Nom),(V15/2)+$O15) -> 12.191489 | X15: =IF($O15<((V48_Max-V12_Nom)*V12_Nom)/((2*Lm*Fsw)*V48_Max),SQRT((2*$O15*Lm*Fsw*V12_Nom)/(V48_Max*(V48_Max-V12_Nom))),(V12_Nom/V48_Max)) -> 0.23529412 | Y15: =IF($O15<((V48_Max-V12_Nom)*V12_Nom)/((2*Lm*Fsw)*V48_Max),SQRT((2*$O15*Lm*Fsw*V12_Nom)/(V48_Max*(V48_Max-V12_Nom)))*((V48_Max-V12_Nom)/(V12_Nom)),1-(V12_Nom/V48_Max)) -> 0.76470588 | Z15: =IF($O15<((V48_Max-V12_Nom)*V12_Nom)/((2*Lm*Fsw)*V48_Max),(X15/(Fsw*Lm))*(V48_Max-V12_Nom),((X15/(Fsw*Lm))*(V48_Max-V12_Nom))) -> 8.135169 | AA15: =IF($O15<((V48_Max-V12_Nom)*V12_Nom)/((2*Lm*Fsw)*V48_Max),(X15/(Fsw*Lm))*(V48_Max-V12_Nom),(Z15/2)+$O15) -> 13.067584 | AB15: =IF($O15<((V48_Nom-V12_Min)*V12_Min)/((2*Lm*Fsw)*V48_Nom),SQRT((2*$O15*Lm*Fsw*V12_Min)/(V48_Nom*(V48_Nom-V12_Min))),(V12_Min/V48_Nom)) -> 0.37 | AC15: =IF($O15<((V48_Nom-V12_Min)*V12_Min)/((2*Lm*Fsw)*V48_Nom),SQRT((2*$O15*Lm*Fsw*V12_Min)/(V48_Nom*(V48_Nom-V12_Min)))*((V48_Nom-V12_Min)/(V12_Min)),1-(V12_Min/V48_Nom)) -> 0.63 | AD15: =IF($O15<((V48_Nom-V12_Min)*V12_Min)/((2*Lm*Fsw)*V48_Nom),(AB15/(Fsw*Lm))*(V48_Nom-V12_Min),((AB15/(Fsw*Lm))*(V48_Nom-V12_Min))) -> 6.1994681 | AE15: =IF($O15<((V48_Nom-V12_Min)*V12_Min)/((2*Lm*Fsw)*V48_Nom),(AB15/(Fsw*Lm))*(V48_Nom-V12_Min),(AD15/2)+$O15) -> 12.099734 | AF15: =IF($O15<((V48_Nom-V12_Nom)*V12_Nom)/((2*Lm*Fsw)*V48_Nom),SQRT((2*$O15*Lm*Fsw*V12_Nom)/(V48_Nom*(V48_Nom-V12_Nom))),(V12_Nom/V48_Nom)) -> 0.4 | AG15: =IF($O15<((V48_Nom-V12_Nom)*V12_Nom)/((2*Lm*Fsw)*V48_Nom),SQRT((2*$O15*Lm*Fsw*V12_Nom)/(V48_Nom*(V48_Nom-V12_Nom)))*((V48_Nom-V12_Nom)/(V12_Nom)),1-(V12_Nom/V48_Nom)) -> 0.6 | AH15: =IF($O15<((V48_Nom-V12_Nom)*V12_Nom)/((2*Lm*Fsw)*V48_Nom),(AF15/(Fsw*Lm))*(V48_Nom-V12_Nom),((AF15/(Fsw*Lm))*(V48_Nom-V12_Nom))) -> 6.3829787 | AI15: =IF($O15<((V48_Nom-V12_Nom)*V12_Nom)/((2*Lm*Fsw)*V48_Nom),(AF15/(Fsw*Lm))*(V48_Nom-V12_Nom),(AH15/2)+$O15) -> 12.191489 | AJ15: =IF($O15<((V48_Nom-V12_Max)*V12_Max)/((2*Lm*Fsw)*V48_Nom),SQRT((2*$O15*Lm*Fsw*V12_Max)/(V48_Nom*(V48_Nom-V12_Max))),(V12_Max/V48_Nom)) -> 0.52 | AK15: =IF($O15<((V48_Nom-V12_Max)*V12_Max)/((2*Lm*Fsw)*V48_Nom),SQRT((2*$O15*Lm*Fsw*V12_Max)/(V48_Nom*(V48_Nom-V12_Max)))*((V48_Nom-V12_Max)/(V12_Max)),1-(V12_Max/V48_Nom)) -> 0.48 | AL15: =IF($O15<((V48_Nom-V12_Max)*V12_Max)/((2*Lm*Fsw)*V48_Nom),(AJ15/(Fsw*Lm))*(V48_Nom-V12_Max),((AJ15/(Fsw*Lm))*(V48_Nom-V12_Max))) -> 6.6382979 | AM15: =IF($O15<((V48_Nom-V12_Max)*V12_Max)/((2*Lm*Fsw)*V48_Nom),(AJ15/(Fsw*Lm))*(V48_Nom-V12_Max),(AL15/2)+$O15) -> 12.319149
A16: RT | B16: =Constants!C17/(Fsw*1000) -> 10 | C16: kOhm | D16: x | E16: Oscilator set resistor Resistor | N16: 0.01 | O16: =N16/Rcs -> 10 | P16: =IF($O16<((V48_Min-V12_Nom)*V12_Nom)/((2*Lm*Fsw)*V48_Min),SQRT((2*$O16*Lm*Fsw*V12_Nom)/(V48_Min*(V48_Min-V12_Nom))),(V12_Nom/V48_Min)) -> 0.66666667 | Q16: =IF($O16<((V48_Min-V12_Nom)*V12_Nom)/((2*Lm*Fsw)*V48_Min),SQRT((2*$O16*Lm*Fsw*V12_Nom)/(V48_Min*(V48_Min-V12_Nom)))*((V48_Min-V12_Nom)/(V12_Nom)),1-(V12_Nom/V48_Min)) -> 0.33333333 | R16: =IF($O16<((V48_Min-V12_Nom)*V12_Nom)/((2*Lm*Fsw)*V48_Min),(P16/(Fsw*Lm))*(V48_Min-V12_Nom),((P16/(Fsw*Lm))*(V48_Min-V12_Nom))) -> 3.5460993 | S16: =IF($O16<((V48_Min-V12_Nom)*V12_Nom)/((2*Lm*Fsw)*V48_Min),(P16/(Fsw*Lm))*(V48_Min-V12_Nom),(R16/2)+$O16) -> 11.77305 | T16: =IF($O16<((V48_Nom-V12_Nom)*V12_Nom)/((2*Lm*Fsw)*V48_Nom),SQRT((2*$O16*Lm*Fsw*V12_Nom)/(V48_Nom*(V48_Nom-V12_Nom))),(V12_Nom/V48_Nom)) -> 0.4 | U16: =IF($O16<((V48_Nom-V12_Nom)*V12_Nom)/((2*Lm*Fsw)*V48_Nom),SQRT((2*$O16*Lm*Fsw*V12_Nom)/(V48_Nom*(V48_Nom-V12_Nom)))*((V48_Nom-V12_Nom)/(V12_Nom)),1-(V12_Nom/V48_Nom)) -> 0.6 | V16: =IF($O16<((V48_Nom-V12_Nom)*V12_Nom)/((2*Lm*Fsw)*V48_Nom),(T16/(Fsw*Lm))*(V48_Nom-V12_Nom),((T16/(Fsw*Lm))*(V48_Nom-V12_Nom))) -> 6.3829787 | W16: =IF($O16<((V48_Nom-V12_Nom)*V12_Nom)/((2*Lm*Fsw)*V48_Nom),(T16/(Fsw*Lm))*(V48_Nom-V12_Nom),(V16/2)+$O16) -> 13.191489 | X16: =IF($O16<((V48_Max-V12_Nom)*V12_Nom)/((2*Lm*Fsw)*V48_Max),SQRT((2*$O16*Lm*Fsw*V12_Nom)/(V48_Max*(V48_Max-V12_Nom))),(V12_Nom/V48_Max)) -> 0.23529412 | Y16: =IF($O16<((V48_Max-V12_Nom)*V12_Nom)/((2*Lm*Fsw)*V48_Max),SQRT((2*$O16*Lm*Fsw*V12_Nom)/(V48_Max*(V48_Max-V12_Nom)))*((V48_Max-V12_Nom)/(V12_Nom)),1-(V12_Nom/V48_Max)) -> 0.76470588 | Z16: =IF($O16<((V48_Max-V12_Nom)*V12_Nom)/((2*Lm*Fsw)*V48_Max),(X16/(Fsw*Lm))*(V48_Max-V12_Nom),((X16/(Fsw*Lm))*(V48_Max-V12_Nom))) -> 8.135169 | AA16: =IF($O16<((V48_Max-V12_Nom)*V12_Nom)/((2*Lm*Fsw)*V48_Max),(X16/(Fsw*Lm))*(V48_Max-V12_Nom),(Z16/2)+$O16) -> 14.067584 | AB16: =IF($O16<((V48_Nom-V12_Min)*V12_Min)/((2*Lm*Fsw)*V48_Nom),SQRT((2*$O16*Lm*Fsw*V12_Min)/(V48_Nom*(V48_Nom-V12_Min))),(V12_Min/V48_Nom)) -> 0.37 | AC16: =IF($O16<((V48_Nom-V12_Min)*V12_Min)/((2*Lm*Fsw)*V48_Nom),SQRT((2*$O16*Lm*Fsw*V12_Min)/(V48_Nom*(V48_Nom-V12_Min)))*((V48_Nom-V12_Min)/(V12_Min)),1-(V12_Min/V48_Nom)) -> 0.63 | AD16: =IF($O16<((V48_Nom-V12_Min)*V12_Min)/((2*Lm*Fsw)*V48_Nom),(AB16/(Fsw*Lm))*(V48_Nom-V12_Min),((AB16/(Fsw*Lm))*(V48_Nom-V12_Min))) -> 6.1994681 | AE16: =IF($O16<((V48_Nom-V12_Min)*V12_Min)/((2*Lm*Fsw)*V48_Nom),(AB16/(Fsw*Lm))*(V48_Nom-V12_Min),(AD16/2)+$O16) -> 13.099734 | AF16: =IF($O16<((V48_Nom-V12_Nom)*V12_Nom)/((2*Lm*Fsw)*V48_Nom),SQRT((2*$O16*Lm*Fsw*V12_Nom)/(V48_Nom*(V48_Nom-V12_Nom))),(V12_Nom/V48_Nom)) -> 0.4 | AG16: =IF($O16<((V48_Nom-V12_Nom)*V12_Nom)/((2*Lm*Fsw)*V48_Nom),SQRT((2*$O16*Lm*Fsw*V12_Nom)/(V48_Nom*(V48_Nom-V12_Nom)))*((V48_Nom-V12_Nom)/(V12_Nom)),1-(V12_Nom/V48_Nom)) -> 0.6 | AH16: =IF($O16<((V48_Nom-V12_Nom)*V12_Nom)/((2*Lm*Fsw)*V48_Nom),(AF16/(Fsw*Lm))*(V48_Nom-V12_Nom),((AF16/(Fsw*Lm))*(V48_Nom-V12_Nom))) -> 6.3829787 | AI16: =IF($O16<((V48_Nom-V12_Nom)*V12_Nom)/((2*Lm*Fsw)*V48_Nom),(AF16/(Fsw*Lm))*(V48_Nom-V12_Nom),(AH16/2)+$O16) -> 13.191489 | AJ16: =IF($O16<((V48_Nom-V12_Max)*V12_Max)/((2*Lm*Fsw)*V48_Nom),SQRT((2*$O16*Lm*Fsw*V12_Max)/(V48_Nom*(V48_Nom-V12_Max))),(V12_Max/V48_Nom)) -> 0.52 | AK16: =IF($O16<((V48_Nom-V12_Max)*V12_Max)/((2*Lm*Fsw)*V48_Nom),SQRT((2*$O16*Lm*Fsw*V12_Max)/(V48_Nom*(V48_Nom-V12_Max)))*((V48_Nom-V12_Max)/(V12_Max)),1-(V12_Max/V48_Nom)) -> 0.48 | AL16: =IF($O16<((V48_Nom-V12_Max)*V12_Max)/((2*Lm*Fsw)*V48_Nom),(AJ16/(Fsw*Lm))*(V48_Nom-V12_Max),((AJ16/(Fsw*Lm))*(V48_Nom-V12_Max))) -> 6.6382979 | AM16: =IF($O16<((V48_Nom-V12_Max)*V12_Max)/((2*Lm*Fsw)*V48_Nom),(AJ16/(Fsw*Lm))*(V48_Nom-V12_Max),(AL16/2)+$O16) -> 13.319149
A17: Minmum Off Time (Buck) | B17: =(1-(V12_Max/V48_Min))/Fsw -> 3.3333333e-07 | C17: s | D17: =IF(B17<Constants!C3,1,0) -> 0 | N17: 0.011 | O17: =N17/Rcs -> 11 | P17: =IF($O17<((V48_Min-V12_Nom)*V12_Nom)/((2*Lm*Fsw)*V48_Min),SQRT((2*$O17*Lm*Fsw*V12_Nom)/(V48_Min*(V48_Min-V12_Nom))),(V12_Nom/V48_Min)) -> 0.66666667 | Q17: =IF($O17<((V48_Min-V12_Nom)*V12_Nom)/((2*Lm*Fsw)*V48_Min),SQRT((2*$O17*Lm*Fsw*V12_Nom)/(V48_Min*(V48_Min-V12_Nom)))*((V48_Min-V12_Nom)/(V12_Nom)),1-(V12_Nom/V48_Min)) -> 0.33333333 | R17: =IF($O17<((V48_Min-V12_Nom)*V12_Nom)/((2*Lm*Fsw)*V48_Min),(P17/(Fsw*Lm))*(V48_Min-V12_Nom),((P17/(Fsw*Lm))*(V48_Min-V12_Nom))) -> 3.5460993 | S17: =IF($O17<((V48_Min-V12_Nom)*V12_Nom)/((2*Lm*Fsw)*V48_Min),(P17/(Fsw*Lm))*(V48_Min-V12_Nom),(R17/2)+$O17) -> 12.77305 | T17: =IF($O17<((V48_Nom-V12_Nom)*V12_Nom)/((2*Lm*Fsw)*V48_Nom),SQRT((2*$O17*Lm*Fsw*V12_Nom)/(V48_Nom*(V48_Nom-V12_Nom))),(V12_Nom/V48_Nom)) -> 0.4 | U17: =IF($O17<((V48_Nom-V12_Nom)*V12_Nom)/((2*Lm*Fsw)*V48_Nom),SQRT((2*$O17*Lm*Fsw*V12_Nom)/(V48_Nom*(V48_Nom-V12_Nom)))*((V48_Nom-V12_Nom)/(V12_Nom)),1-(V12_Nom/V48_Nom)) -> 0.6 | V17: =IF($O17<((V48_Nom-V12_Nom)*V12_Nom)/((2*Lm*Fsw)*V48_Nom),(T17/(Fsw*Lm))*(V48_Nom-V12_Nom),((T17/(Fsw*Lm))*(V48_Nom-V12_Nom))) -> 6.3829787 | W17: =IF($O17<((V48_Nom-V12_Nom)*V12_Nom)/((2*Lm*Fsw)*V48_Nom),(T17/(Fsw*Lm))*(V48_Nom-V12_Nom),(V17/2)+$O17) -> 14.191489 | X17: =IF($O17<((V48_Max-V12_Nom)*V12_Nom)/((2*Lm*Fsw)*V48_Max),SQRT((2*$O17*Lm*Fsw*V12_Nom)/(V48_Max*(V48_Max-V12_Nom))),(V12_Nom/V48_Max)) -> 0.23529412 | Y17: =IF($O17<((V48_Max-V12_Nom)*V12_Nom)/((2*Lm*Fsw)*V48_Max),SQRT((2*$O17*Lm*Fsw*V12_Nom)/(V48_Max*(V48_Max-V12_Nom)))*((V48_Max-V12_Nom)/(V12_Nom)),1-(V12_Nom/V48_Max)) -> 0.76470588 | Z17: =IF($O17<((V48_Max-V12_Nom)*V12_Nom)/((2*Lm*Fsw)*V48_Max),(X17/(Fsw*Lm))*(V48_Max-V12_Nom),((X17/(Fsw*Lm))*(V48_Max-V12_Nom))) -> 8.135169 | AA17: =IF($O17<((V48_Max-V12_Nom)*V12_Nom)/((2*Lm*Fsw)*V48_Max),(X17/(Fsw*Lm))*(V48_Max-V12_Nom),(Z17/2)+$O17) -> 15.067584 | AB17: =IF($O17<((V48_Nom-V12_Min)*V12_Min)/((2*Lm*Fsw)*V48_Nom),SQRT((2*$O17*Lm*Fsw*V12_Min)/(V48_Nom*(V48_Nom-V12_Min))),(V12_Min/V48_Nom)) -> 0.37 | AC17: =IF($O17<((V48_Nom-V12_Min)*V12_Min)/((2*Lm*Fsw)*V48_Nom),SQRT((2*$O17*Lm*Fsw*V12_Min)/(V48_Nom*(V48_Nom-V12_Min)))*((V48_Nom-V12_Min)/(V12_Min)),1-(V12_Min/V48_Nom)) -> 0.63 | AD17: =IF($O17<((V48_Nom-V12_Min)*V12_Min)/((2*Lm*Fsw)*V48_Nom),(AB17/(Fsw*Lm))*(V48_Nom-V12_Min),((AB17/(Fsw*Lm))*(V48_Nom-V12_Min))) -> 6.1994681 | AE17: =IF($O17<((V48_Nom-V12_Min)*V12_Min)/((2*Lm*Fsw)*V48_Nom),(AB17/(Fsw*Lm))*(V48_Nom-V12_Min),(AD17/2)+$O17) -> 14.099734 | AF17: =IF($O17<((V48_Nom-V12_Nom)*V12_Nom)/((2*Lm*Fsw)*V48_Nom),SQRT((2*$O17*Lm*Fsw*V12_Nom)/(V48_Nom*(V48_Nom-V12_Nom))),(V12_Nom/V48_Nom)) -> 0.4 | AG17: =IF($O17<((V48_Nom-V12_Nom)*V12_Nom)/((2*Lm*Fsw)*V48_Nom),SQRT((2*$O17*Lm*Fsw*V12_Nom)/(V48_Nom*(V48_Nom-V12_Nom)))*((V48_Nom-V12_Nom)/(V12_Nom)),1-(V12_Nom/V48_Nom)) -> 0.6 | AH17: =IF($O17<((V48_Nom-V12_Nom)*V12_Nom)/((2*Lm*Fsw)*V48_Nom),(AF17/(Fsw*Lm))*(V48_Nom-V12_Nom),((AF17/(Fsw*Lm))*(V48_Nom-V12_Nom))) -> 6.3829787 | AI17: =IF($O17<((V48_Nom-V12_Nom)*V12_Nom)/((2*Lm*Fsw)*V48_Nom),(AF17/(Fsw*Lm))*(V48_Nom-V12_Nom),(AH17/2)+$O17) -> 14.191489 | AJ17: =IF($O17<((V48_Nom-V12_Max)*V12_Max)/((2*Lm*Fsw)*V48_Nom),SQRT((2*$O17*Lm*Fsw*V12_Max)/(V48_Nom*(V48_Nom-V12_Max))),(V12_Max/V48_Nom)) -> 0.52 | AK17: =IF($O17<((V48_Nom-V12_Max)*V12_Max)/((2*Lm*Fsw)*V48_Nom),SQRT((2*$O17*Lm*Fsw*V12_Max)/(V48_Nom*(V48_Nom-V12_Max)))*((V48_Nom-V12_Max)/(V12_Max)),1-(V12_Max/V48_Nom)) -> 0.48 | AL17: =IF($O17<((V48_Nom-V12_Max)*V12_Max)/((2*Lm*Fsw)*V48_Nom),(AJ17/(Fsw*Lm))*(V48_Nom-V12_Max),((AJ17/(Fsw*Lm))*(V48_Nom-V12_Max))) -> 6.6382979 | AM17: =IF($O17<((V48_Nom-V12_Max)*V12_Max)/((2*Lm*Fsw)*V48_Nom),(AJ17/(Fsw*Lm))*(V48_Nom-V12_Max),(AL17/2)+$O17) -> 14.319149
A18: Minmum Off Time (Boost) | B18: =(V12_Min/V48_Max)/Fsw -> 5.4411765e-07 | C18: s | D18: =IF(B18<Constants!C3,1,0) -> 0 | N18: 0.012 | O18: =N18/Rcs -> 12 | P18: =IF($O18<((V48_Min-V12_Nom)*V12_Nom)/((2*Lm*Fsw)*V48_Min),SQRT((2*$O18*Lm*Fsw*V12_Nom)/(V48_Min*(V48_Min-V12_Nom))),(V12_Nom/V48_Min)) -> 0.66666667 | Q18: =IF($O18<((V48_Min-V12_Nom)*V12_Nom)/((2*Lm*Fsw)*V48_Min),SQRT((2*$O18*Lm*Fsw*V12_Nom)/(V48_Min*(V48_Min-V12_Nom)))*((V48_Min-V12_Nom)/(V12_Nom)),1-(V12_Nom/V48_Min)) -> 0.33333333 | R18: =IF($O18<((V48_Min-V12_Nom)*V12_Nom)/((2*Lm*Fsw)*V48_Min),(P18/(Fsw*Lm))*(V48_Min-V12_Nom),((P18/(Fsw*Lm))*(V48_Min-V12_Nom))) -> 3.5460993 | S18: =IF($O18<((V48_Min-V12_Nom)*V12_Nom)/((2*Lm*Fsw)*V48_Min),(P18/(Fsw*Lm))*(V48_Min-V12_Nom),(R18/2)+$O18) -> 13.77305 | T18: =IF($O18<((V48_Nom-V12_Nom)*V12_Nom)/((2*Lm*Fsw)*V48_Nom),SQRT((2*$O18*Lm*Fsw*V12_Nom)/(V48_Nom*(V48_Nom-V12_Nom))),(V12_Nom/V48_Nom)) -> 0.4 | U18: =IF($O18<((V48_Nom-V12_Nom)*V12_Nom)/((2*Lm*Fsw)*V48_Nom),SQRT((2*$O18*Lm*Fsw*V12_Nom)/(V48_Nom*(V48_Nom-V12_Nom)))*((V48_Nom-V12_Nom)/(V12_Nom)),1-(V12_Nom/V48_Nom)) -> 0.6 | V18: =IF($O18<((V48_Nom-V12_Nom)*V12_Nom)/((2*Lm*Fsw)*V48_Nom),(T18/(Fsw*Lm))*(V48_Nom-V12_Nom),((T18/(Fsw*Lm))*(V48_Nom-V12_Nom))) -> 6.3829787 | W18: =IF($O18<((V48_Nom-V12_Nom)*V12_Nom)/((2*Lm*Fsw)*V48_Nom),(T18/(Fsw*Lm))*(V48_Nom-V12_Nom),(V18/2)+$O18) -> 15.191489 | X18: =IF($O18<((V48_Max-V12_Nom)*V12_Nom)/((2*Lm*Fsw)*V48_Max),SQRT((2*$O18*Lm*Fsw*V12_Nom)/(V48_Max*(V48_Max-V12_Nom))),(V12_Nom/V48_Max)) -> 0.23529412 | Y18: =IF($O18<((V48_Max-V12_Nom)*V12_Nom)/((2*Lm*Fsw)*V48_Max),SQRT((2*$O18*Lm*Fsw*V12_Nom)/(V48_Max*(V48_Max-V12_Nom)))*((V48_Max-V12_Nom)/(V12_Nom)),1-(V12_Nom/V48_Max)) -> 0.76470588 | Z18: =IF($O18<((V48_Max-V12_Nom)*V12_Nom)/((2*Lm*Fsw)*V48_Max),(X18/(Fsw*Lm))*(V48_Max-V12_Nom),((X18/(Fsw*Lm))*(V48_Max-V12_Nom))) -> 8.135169 | AA18: =IF($O18<((V48_Max-V12_Nom)*V12_Nom)/((2*Lm*Fsw)*V48_Max),(X18/(Fsw*Lm))*(V48_Max-V12_Nom),(Z18/2)+$O18) -> 16.067584 | AB18: =IF($O18<((V48_Nom-V12_Min)*V12_Min)/((2*Lm*Fsw)*V48_Nom),SQRT((2*$O18*Lm*Fsw*V12_Min)/(V48_Nom*(V48_Nom-V12_Min))),(V12_Min/V48_Nom)) -> 0.37 | AC18: =IF($O18<((V48_Nom-V12_Min)*V12_Min)/((2*Lm*Fsw)*V48_Nom),SQRT((2*$O18*Lm*Fsw*V12_Min)/(V48_Nom*(V48_Nom-V12_Min)))*((V48_Nom-V12_Min)/(V12_Min)),1-(V12_Min/V48_Nom)) -> 0.63 | AD18: =IF($O18<((V48_Nom-V12_Min)*V12_Min)/((2*Lm*Fsw)*V48_Nom),(AB18/(Fsw*Lm))*(V48_Nom-V12_Min),((AB18/(Fsw*Lm))*(V48_Nom-V12_Min))) -> 6.1994681 | AE18: =IF($O18<((V48_Nom-V12_Min)*V12_Min)/((2*Lm*Fsw)*V48_Nom),(AB18/(Fsw*Lm))*(V48_Nom-V12_Min),(AD18/2)+$O18) -> 15.099734 | AF18: =IF($O18<((V48_Nom-V12_Nom)*V12_Nom)/((2*Lm*Fsw)*V48_Nom),SQRT((2*$O18*Lm*Fsw*V12_Nom)/(V48_Nom*(V48_Nom-V12_Nom))),(V12_Nom/V48_Nom)) -> 0.4 | AG18: =IF($O18<((V48_Nom-V12_Nom)*V12_Nom)/((2*Lm*Fsw)*V48_Nom),SQRT((2*$O18*Lm*Fsw*V12_Nom)/(V48_Nom*(V48_Nom-V12_Nom)))*((V48_Nom-V12_Nom)/(V12_Nom)),1-(V12_Nom/V48_Nom)) -> 0.6 | AH18: =IF($O18<((V48_Nom-V12_Nom)*V12_Nom)/((2*Lm*Fsw)*V48_Nom),(AF18/(Fsw*Lm))*(V48_Nom-V12_Nom),((AF18/(Fsw*Lm))*(V48_Nom-V12_Nom))) -> 6.3829787 | AI18: =IF($O18<((V48_Nom-V12_Nom)*V12_Nom)/((2*Lm*Fsw)*V48_Nom),(AF18/(Fsw*Lm))*(V48_Nom-V12_Nom),(AH18/2)+$O18) -> 15.191489 | AJ18: =IF($O18<((V48_Nom-V12_Max)*V12_Max)/((2*Lm*Fsw)*V48_Nom),SQRT((2*$O18*Lm*Fsw*V12_Max)/(V48_Nom*(V48_Nom-V12_Max))),(V12_Max/V48_Nom)) -> 0.52 | AK18: =IF($O18<((V48_Nom-V12_Max)*V12_Max)/((2*Lm*Fsw)*V48_Nom),SQRT((2*$O18*Lm*Fsw*V12_Max)/(V48_Nom*(V48_Nom-V12_Max)))*((V48_Nom-V12_Max)/(V12_Max)),1-(V12_Max/V48_Nom)) -> 0.48 | AL18: =IF($O18<((V48_Nom-V12_Max)*V12_Max)/((2*Lm*Fsw)*V48_Nom),(AJ18/(Fsw*Lm))*(V48_Nom-V12_Max),((AJ18/(Fsw*Lm))*(V48_Nom-V12_Max))) -> 6.6382979 | AM18: =IF($O18<((V48_Nom-V12_Max)*V12_Max)/((2*Lm*Fsw)*V48_Nom),(AJ18/(Fsw*Lm))*(V48_Nom-V12_Max),(AL18/2)+$O18) -> 15.319149
N19: 0.013 | O19: =N19/Rcs -> 13 | P19: =IF($O19<((V48_Min-V12_Nom)*V12_Nom)/((2*Lm*Fsw)*V48_Min),SQRT((2*$O19*Lm*Fsw*V12_Nom)/(V48_Min*(V48_Min-V12_Nom))),(V12_Nom/V48_Min)) -> 0.66666667 | Q19: =IF($O19<((V48_Min-V12_Nom)*V12_Nom)/((2*Lm*Fsw)*V48_Min),SQRT((2*$O19*Lm*Fsw*V12_Nom)/(V48_Min*(V48_Min-V12_Nom)))*((V48_Min-V12_Nom)/(V12_Nom)),1-(V12_Nom/V48_Min)) -> 0.33333333 | R19: =IF($O19<((V48_Min-V12_Nom)*V12_Nom)/((2*Lm*Fsw)*V48_Min),(P19/(Fsw*Lm))*(V48_Min-V12_Nom),((P19/(Fsw*Lm))*(V48_Min-V12_Nom))) -> 3.5460993 | S19: =IF($O19<((V48_Min-V12_Nom)*V12_Nom)/((2*Lm*Fsw)*V48_Min),(P19/(Fsw*Lm))*(V48_Min-V12_Nom),(R19/2)+$O19) -> 14.77305 | T19: =IF($O19<((V48_Nom-V12_Nom)*V12_Nom)/((2*Lm*Fsw)*V48_Nom),SQRT((2*$O19*Lm*Fsw*V12_Nom)/(V48_Nom*(V48_Nom-V12_Nom))),(V12_Nom/V48_Nom)) -> 0.4 | U19: =IF($O19<((V48_Nom-V12_Nom)*V12_Nom)/((2*Lm*Fsw)*V48_Nom),SQRT((2*$O19*Lm*Fsw*V12_Nom)/(V48_Nom*(V48_Nom-V12_Nom)))*((V48_Nom-V12_Nom)/(V12_Nom)),1-(V12_Nom/V48_Nom)) -> 0.6 | V19: =IF($O19<((V48_Nom-V12_Nom)*V12_Nom)/((2*Lm*Fsw)*V48_Nom),(T19/(Fsw*Lm))*(V48_Nom-V12_Nom),((T19/(Fsw*Lm))*(V48_Nom-V12_Nom))) -> 6.3829787 | W19: =IF($O19<((V48_Nom-V12_Nom)*V12_Nom)/((2*Lm*Fsw)*V48_Nom),(T19/(Fsw*Lm))*(V48_Nom-V12_Nom),(V19/2)+$O19) -> 16.191489 | X19: =IF($O19<((V48_Max-V12_Nom)*V12_Nom)/((2*Lm*Fsw)*V48_Max),SQRT((2*$O19*Lm*Fsw*V12_Nom)/(V48_Max*(V48_Max-V12_Nom))),(V12_Nom/V48_Max)) -> 0.23529412 | Y19: =IF($O19<((V48_Max-V12_Nom)*V12_Nom)/((2*Lm*Fsw)*V48_Max),SQRT((2*$O19*Lm*Fsw*V12_Nom)/(V48_Max*(V48_Max-V12_Nom)))*((V48_Max-V12_Nom)/(V12_Nom)),1-(V12_Nom/V48_Max)) -> 0.76470588 | Z19: =IF($O19<((V48_Max-V12_Nom)*V12_Nom)/((2*Lm*Fsw)*V48_Max),(X19/(Fsw*Lm))*(V48_Max-V12_Nom),((X19/(Fsw*Lm))*(V48_Max-V12_Nom))) -> 8.135169 | AA19: =IF($O19<((V48_Max-V12_Nom)*V12_Nom)/((2*Lm*Fsw)*V48_Max),(X19/(Fsw*Lm))*(V48_Max-V12_Nom),(Z19/2)+$O19) -> 17.067584 | AB19: =IF($O19<((V48_Nom-V12_Min)*V12_Min)/((2*Lm*Fsw)*V48_Nom),SQRT((2*$O19*Lm*Fsw*V12_Min)/(V48_Nom*(V48_Nom-V12_Min))),(V12_Min/V48_Nom)) -> 0.37 | AC19: =IF($O19<((V48_Nom-V12_Min)*V12_Min)/((2*Lm*Fsw)*V48_Nom),SQRT((2*$O19*Lm*Fsw*V12_Min)/(V48_Nom*(V48_Nom-V12_Min)))*((V48_Nom-V12_Min)/(V12_Min)),1-(V12_Min/V48_Nom)) -> 0.63 | AD19: =IF($O19<((V48_Nom-V12_Min)*V12_Min)/((2*Lm*Fsw)*V48_Nom),(AB19/(Fsw*Lm))*(V48_Nom-V12_Min),((AB19/(Fsw*Lm))*(V48_Nom-V12_Min))) -> 6.1994681 | AE19: =IF($O19<((V48_Nom-V12_Min)*V12_Min)/((2*Lm*Fsw)*V48_Nom),(AB19/(Fsw*Lm))*(V48_Nom-V12_Min),(AD19/2)+$O19) -> 16.099734 | AF19: =IF($O19<((V48_Nom-V12_Nom)*V12_Nom)/((2*Lm*Fsw)*V48_Nom),SQRT((2*$O19*Lm*Fsw*V12_Nom)/(V48_Nom*(V48_Nom-V12_Nom))),(V12_Nom/V48_Nom)) -> 0.4 | AG19: =IF($O19<((V48_Nom-V12_Nom)*V12_Nom)/((2*Lm*Fsw)*V48_Nom),SQRT((2*$O19*Lm*Fsw*V12_Nom)/(V48_Nom*(V48_Nom-V12_Nom)))*((V48_Nom-V12_Nom)/(V12_Nom)),1-(V12_Nom/V48_Nom)) -> 0.6 | AH19: =IF($O19<((V48_Nom-V12_Nom)*V12_Nom)/((2*Lm*Fsw)*V48_Nom),(AF19/(Fsw*Lm))*(V48_Nom-V12_Nom),((AF19/(Fsw*Lm))*(V48_Nom-V12_Nom))) -> 6.3829787 | AI19: =IF($O19<((V48_Nom-V12_Nom)*V12_Nom)/((2*Lm*Fsw)*V48_Nom),(AF19/(Fsw*Lm))*(V48_Nom-V12_Nom),(AH19/2)+$O19) -> 16.191489 | AJ19: =IF($O19<((V48_Nom-V12_Max)*V12_Max)/((2*Lm*Fsw)*V48_Nom),SQRT((2*$O19*Lm*Fsw*V12_Max)/(V48_Nom*(V48_Nom-V12_Max))),(V12_Max/V48_Nom)) -> 0.52 | AK19: =IF($O19<((V48_Nom-V12_Max)*V12_Max)/((2*Lm*Fsw)*V48_Nom),SQRT((2*$O19*Lm*Fsw*V12_Max)/(V48_Nom*(V48_Nom-V12_Max)))*((V48_Nom-V12_Max)/(V12_Max)),1-(V12_Max/V48_Nom)) -> 0.48 | AL19: =IF($O19<((V48_Nom-V12_Max)*V12_Max)/((2*Lm*Fsw)*V48_Nom),(AJ19/(Fsw*Lm))*(V48_Nom-V12_Max),((AJ19/(Fsw*Lm))*(V48_Nom-V12_Max))) -> 6.6382979 | AM19: =IF($O19<((V48_Nom-V12_Max)*V12_Max)/((2*Lm*Fsw)*V48_Nom),(AJ19/(Fsw*Lm))*(V48_Nom-V12_Max),(AL19/2)+$O19) -> 16.319149
